Workbook
Name rCOPY: '8. 추정 BS'!$F$65:$K$65
Name rCOPY_RT: '11. 추정 BS'!$D$144:$K$144
Name rPASTE: '8. 추정 BS'!$F$8:$K$8
Name rPASTE_RT: '11. 추정 BS'!$D$18:$K$18

Sheet ▶ REPORT

Sheet 1. 요약재무제표
E1: 숨김
A2: ■ 요약 재무제표
Q3: (단위 : 백만원)
A4: 구 분 | E4: 2020년 | G4: 2021년 | I4: 2022년 | K4: 2023년 | M4: 2024년 | O4: 2025년 | Q4: 비 고 | T4: 구 분 | X4: 2016 | Z4: 2017 | AB4: 2018 | AD4: 2019 | AF4: 2020
F5: 증감률 | H5: 증감률 | J5: 증감률 | L5: 증감률 | N5: 증감률 | P5: 증감률 | X5: 금액 | Y5: 증감률 | Z5: 금액 | AA5: 증감률 | AB5: 금액 | AC5: 증감률 | AD5: 금액 | AE5: 증감률 | AF5: 금액 | AG5: 증감률 | AS5: 2021 | AU5: 2022 | AW5: 2023 | AY5: 2024 | BA5: 2025 | BE5: 공시
A6: 요약재무상태표 | B6: 자산총계 | E6: =SUM(E7:E8) -> 1561615.4 | G6: =SUM(G7:G8) -> 7678930.3 | H6: =IF(OR(E6<=0,G6<=0),0,G6/E6-1) -> 3.9172993 | I6: =SUM(I7:I8) -> 7951326.7 | J6: =IF(OR(G6<=0,I6<=0),0,I6/G6-1) -> 0.035473229 | K6: =SUM(K7:K8) -> 8218723.2 | L6: =IF(OR(I6<=0,K6<=0),0,K6/I6-1) -> 0.033629171 | M6: =SUM(M7:M8) -> 7155550.5 | N6: =IF(OR(K6<=0,M6<=0),0,M6/K6-1) -> -0.12935984 | O6: =SUM(O7:O8) -> 7121336.9 | P6: =IF(OR(M6<=0,O6<=0),0,O6/M6-1) -> -0.0047814114 | T6: 요약 | U6: 자산총계 | X6: 1355211 | Y6: 9.4 | Z6: 1424846 | AA6: 5.1 | AB6: 1384202 | AC6: -2.9 | AD6: 1426568 | AE6: 3.1 | AF6: 1561615 | AG6: 9.5 | AI6: =#REF!-X6 -> #REF! | AJ6: =#REF!-Z6 -> #REF! | AK6: =E6-AB6 -> 177413.4 | AL6: =G6-AD6 -> 6252362.3 | AM6: =I6-AF6 -> 6389711.7 | AN6: =(AF6-AD6)/AD6 -> 0.094665659 | AO6: =AN6*100 -> 9.4665659 | AP6: =AG6-AO6 -> 0.033434088 | AR6: 자산총계 | AS6: 7678930254664 | AT6: =G6*1000000-AS6 -> 0 | AU6: 7951326708929 | AV6: =I6*1000000-AU6 -> 0 | AW6: 8218723236460 | AX6: =K6*1000000-AW6 -> 0 | AY6: 7155550486165 | AZ6: =M6*1000000-AY6 -> 0 | BA6: ='SAP BS'!G13 -> 7121336855838 | BB6: =O6*1000000-BA6 -> 0 | BD6: 자 산 총 계 | BE6: 7121336855838 | BG6: =BA6-BE6 -> 0
C7: 유동자산 | E7: 740920.78 | G7: =AS7/1000000 -> 955684.4 | H7: =IF(OR(E7<=0,G7<=0),0,G7/E7-1) -> 0.28986043 | I7: =AU7/1000000 -> 1219864.9 | J7: =IF(OR(G7<=0,I7<=0),0,I7/G7-1) -> 0.27643067 | K7: =AW7/1000000 -> 1716841.6 | L7: =IF(OR(I7<=0,K7<=0),0,K7/I7-1) -> 0.40740308 | M7: =AY7/1000000 -> 1422091.6 | N7: =IF(OR(K7<=0,M7<=0),0,M7/K7-1) -> -0.17168156 | O7: =BA7/1000000 -> 1670299 | P7: =IF(OR(M7<=0,O7<=0),0,O7/M7-1) -> 0.17453688 | T7: 재무 | V7: 유동자산 | X7: 811777 | Y7: 14.9 | Z7: 733619 | AA7: -9.6 | AB7: 710950 | AC7: -3.1 | AD7: 642134 | AE7: -9.7 | AF7: 740921 | AG7: 15.4 | AI7: =#REF!-X7 -> #REF! | AJ7: =#REF!-Z7 -> #REF! | AK7: =E7-AB7 -> 29970.785 | AL7: =G7-AD7 -> 313550.4 | AM7: =I7-AF7 -> 478943.88 | AN7: =(AF7-AD7)/AD7 -> 0.15384172 | AO7: =AN7*100 -> 15.384172 | AP7: =AG7-AO7 -> 0.015827849 | AR7: 유동자산 | AS7: 955684403335 | AT7: =G7*1000000-AS7 -> 0 | AU7: 1219864882877 | AV7: =I7*1000000-AU7 -> 0 | AW7: 1716841596021 | AX7: =K7*1000000-AW7 -> 0 | AY7: 1422091558149 | AZ7: =M7*1000000-AY7 -> 0 | BA7: ='SAP BS'!G14 -> 1670298975069 | BB7: =O7*1000000-BA7 -> 0 | BD7: Ⅰ. 유동자산 | BE7: 1670298975069 | BG7: =BA7-BE7 -> 0
C8: 비유동자산 | E8: 820694.62 | G8: =AS8/1000000 -> 6723245.9 | H8: =IF(OR(E8<=0,G8<=0),0,G8/E8-1) -> 7.1921408 | I8: =AU8/1000000 -> 6731461.8 | J8: =IF(OR(G8<=0,I8<=0),0,I8/G8-1) -> 0.001222025 | K8: =AW8/1000000 -> 6501881.6 | L8: =IF(OR(I8<=0,K8<=0),0,K8/I8-1) -> -0.034105547 | M8: =AY8/1000000 -> 5733458.9 | N8: =IF(OR(K8<=0,M8<=0),0,M8/K8-1) -> -0.11818467 | O8: =BA8/1000000 -> 5451037.9 | P8: =IF(OR(M8<=0,O8<=0),0,O8/M8-1) -> -0.049258406 | T8: 상태표 | V8: 비유동자산 | X8: 543434 | Y8: 2 | Z8: 691227 | AA8: 27.2 | AB8: 673252 | AC8: -2.6 | AD8: 784435 | AE8: 16.5 | AF8: 820694 | AG8: 4.6 | AI8: =#REF!-X8 -> #REF! | AJ8: =#REF!-Z8 -> #REF! | AK8: =E8-AB8 -> 147442.62 | AL8: =G8-AD8 -> 5938810.9 | AM8: =I8-AF8 -> 5910767.8 | AN8: =(AF8-AD8)/AD8 -> 0.046223078 | AO8: =AN8*100 -> 4.6223078 | AP8: =AG8-AO8 -> -0.022307776 | AR8: 비유동자산 | AS8: 6723245851329 | AT8: =G8*1000000-AS8 -> 0 | AU8: 6731461826052 | AV8: =I8*1000000-AU8 -> 0 | AW8: 6501881640439 | AX8: =K8*1000000-AW8 -> 0 | AY8: 5733458928016 | AZ8: =M8*1000000-AY8 -> 0 | BA8: ='SAP BS'!G2698 -> 5451037880769 | BB8: =O8*1000000-BA8 -> 0 | BD8: Ⅱ. 비유동자산 | BE8: 5451037880769 | BG8: =BA8-BE8 -> 0
B9: 부채총계 | E9: =SUM(E10:E11) -> 312867.67 | G9: =SUM(G10:G11) -> 3567657.8 | H9: =IF(OR(E9<=0,G9<=0),0,G9/E9-1) -> 10.403089 | I9: =SUM(I10:I11) -> 3841536.7 | J9: =IF(OR(G9<=0,I9<=0),0,I9/G9-1) -> 0.076767145 | K9: =SUM(K10:K11) -> 4136190.6 | L9: =IF(OR(I9<=0,K9<=0),0,K9/I9-1) -> 0.076702094 | M9: =SUM(M10:M11) -> 3953186.4 | N9: =IF(OR(K9<=0,M9<=0),0,M9/K9-1) -> -0.044244607 | O9: =SUM(O10:O11) -> 3796297.1 | P9: =IF(OR(M9<=0,O9<=0),0,O9/M9-1) -> -0.039686795 | U9: 부채총계 | X9: 363639 | Y9: 18.7 | Z9: 341693 | AA9: -6 | AB9: 291047 | AC9: -14.8 | AD9: 281309 | AE9: -3.3 | AF9: 312868 | AG9: 11.2 | AI9: =#REF!-X9 -> #REF! | AJ9: =#REF!-Z9 -> #REF! | AK9: =E9-AB9 -> 21820.671 | AL9: =G9-AD9 -> 3286348.8 | AM9: =I9-AF9 -> 3528668.7 | AN9: =(AF9-AD9)/AD9 -> 0.11218624 | AO9: =AN9*100 -> 11.218624 | AP9: =AG9-AO9 -> -0.01862436 | AR9: 부채총계 | AS9: 3567657752579 | AT9: =G9*1000000-AS9 -> 0 | AU9: 3841536654146 | AV9: =I9*1000000-AU9 -> 0 | AW9: 4136190560653 | AX9: =K9*1000000-AW9 -> 0 | AY9: 3953186433697 | AZ9: =M9*1000000-AY9 -> 0 | BA9: ='SAP BS'!G2964 -> 3796297134919 | BB9: =O9*1000000-BA9 -> 0 | BD9: 부 채 총 계 | BE9: 3796297134919 | BG9: =BA9-BE9 -> 0
C10: 유동부채 | E10: 285467.9 | G10: =AS10/1000000 -> 1569402.2 | H10: =IF(OR(E10<=0,G10<=0),0,G10/E10-1) -> 4.4976484 | I10: =AU10/1000000 -> 1726933.3 | J10: =IF(OR(G10<=0,I10<=0),0,I10/G10-1) -> 0.10037656 | K10: =AW10/1000000 -> 2077671 | L10: =IF(OR(I10<=0,K10<=0),0,K10/I10-1) -> 0.20309855 | M10: =AY10/1000000 -> 1747795.2 | N10: =IF(OR(K10<=0,M10<=0),0,M10/K10-1) -> -0.1587719 | O10: =BA10/1000000 -> 1726694.9 | P10: =IF(OR(M10<=0,O10<=0),0,O10/M10-1) -> -0.012072558 | V10: 유동부채 | X10: 357757 | Y10: 20.1 | Z10: 336445 | AA10: -6 | AB10: 284163 | AC10: -15.5 | AD10: 267281 | AE10: -5.9 | AF10: 285467 | AG10: 6.8 | AI10: =#REF!-X10 -> #REF! | AJ10: =#REF!-Z10 -> #REF! | AK10: =E10-AB10 -> 1304.9044 | AL10: =G10-AD10 -> 1302121.2 | AM10: =I10-AF10 -> 1441466.3 | AN10: =(AF10-AD10)/AD10 -> 0.068040751 | AO10: =AN10*100 -> 6.8040751 | AP10: =AG10-AO10 -> -0.004075112 | AR10: 유동부채 | AS10: 1569402154384 | AT10: =G10*1000000-AS10 -> 0 | AU10: 1726933341656 | AV10: =I10*1000000-AU10 -> 0 | AW10: 2077670994040 | AX10: =K10*1000000-AW10 -> 0 | AY10: 1747795229660 | AZ10: =M10*1000000-AY10 -> 0 | BA10: ='SAP BS'!G2965 -> 1726694869549 | BB10: =O10*1000000-BA10 -> 0 | BD10: Ⅰ. 유동부채 | BE10: 1726694869549 | BG10: =BA10-BE10 -> 0
C11: 비유동부채 | E11: 27399.767 | G11: =AS11/1000000 -> 1998255.6 | H11: =IF(OR(E11<=0,G11<=0),0,G11/E11-1) -> 71.929658 | I11: =AU11/1000000 -> 2114603.3 | J11: =IF(OR(G11<=0,I11<=0),0,I11/G11-1) -> 0.058224641 | K11: =AW11/1000000 -> 2058519.6 | L11: =IF(OR(I11<=0,K11<=0),0,K11/I11-1) -> -0.026522112 | M11: =AY11/1000000 -> 2205391.2 | N11: =IF(OR(K11<=0,M11<=0),0,M11/K11-1) -> 0.071348186 | O11: =BA11/1000000 -> 2069602.3 | P11: =IF(OR(M11<=0,O11<=0),0,O11/M11-1) -> -0.061571361 | V11: 비유동부채 | X11: 5881 | Y11: -31.2 | Z11: 5248 | AA11: -10.8 | AB11: 6884 | AC11: 31.2 | AD11: 14028 | AE11: 103.8 | AF11: 27401 | AG11: 95.3 | AI11: =#REF!-X11 -> #REF! | AJ11: =#REF!-Z11 -> #REF! | AK11: =E11-AB11 -> 20515.767 | AL11: =G11-AD11 -> 1984227.6 | AM11: =I11-AF11 -> 2087202.3 | AN11: =(AF11-AD11)/AD11 -> 0.95330767 | AO11: =AN11*100 -> 95.330767 | AP11: =AG11-AO11 -> -0.030767037 | AR11: 비유동부채 | AS11: 1998255598195 | AT11: =G11*1000000-AS11 -> 0 | AU11: 2114603312490 | AV11: =I11*1000000-AU11 -> 0 | AW11: 2058519566613 | AX11: =K11*1000000-AW11 -> 0 | AY11: 2205391204037 | AZ11: =M11*1000000-AY11 -> 0 | BA11: ='SAP BS'!G3169 -> 2069602265370 | BB11: =O11*1000000-BA11 -> 0 | BD11: Ⅱ. 비유동부채 | BE11: 2069602265370 | BG11: =BA11-BE11 -> 0
B12: 자본총계 | E12: =SUM(E13:E17) -> 1248747.7 | G12: =SUM(G13:G17) -> 4111272.5 | H12: =IF(OR(E12<=0,G12<=0),0,G12/E12-1) -> 2.2923163 | I12: =SUM(I13:I17) -> 4109790.1 | J12: =IF(OR(G12<=0,I12<=0),0,I12/G12-1) -> -0.00036058113 | K12: =SUM(K13:K17) -> 4082532.7 | L12: =IF(OR(I12<=0,K12<=0),0,K12/I12-1) -> -0.0066323045 | M12: =SUM(M13:M17) -> 3202364.1 | N12: =IF(OR(K12<=0,M12<=0),0,M12/K12-1) -> -0.21559377 | O12: =SUM(O13:O17) -> 3325039.7 | P12: =IF(OR(M12<=0,O12<=0),0,O12/M12-1) -> 0.038307846 | U12: 자본총계 | X12: 991573 | Y12: 6.3 | Z12: 1083153 | AA12: 9.2 | AB12: 1093155 | AC12: 0.9 | AD12: 1145259 | AE12: 4.8 | AF12: 1248747 | AG12: 9 | AI12: =#REF!-X12 -> #REF! | AJ12: =#REF!-Z12 -> #REF! | AK12: =E12-AB12 -> 155592.73 | AL12: =G12-AD12 -> 2966013.5 | AM12: =I12-AF12 -> 2861043.1 | AN12: =(AF12-AD12)/AD12 -> 0.090362093 | AO12: =AN12*100 -> 9.0362093 | AP12: =AG12-AO12 -> -0.036209277 | AR12: 자본총계 | AS12: 4111272502085 | AT12: =G12*1000000-AS12 -> 0 | AU12: 4109790054783 | AV12: =I12*1000000-AU12 -> 0 | AW12: 4082532675807 | AX12: =K12*1000000-AW12 -> 0 | AY12: 3202364052468 | AZ12: =M12*1000000-AY12 -> 0 | BA12: ='SAP BS'!G3237 -> 3325039720919 | BB12: =O12*1000000-BA12 -> 0 | BD12: 자 본 총 계 | BE12: 3325039720919 | BG12: =BA12-BE12 -> 0
C13: 자본금 | E13: 32812.5 | G13: =AS13/1000000 -> 104717.92 | H13: =IF(OR(E13<=0,G13<=0),0,G13/E13-1) -> 2.1914033 | I13: =AU13/1000000 -> 104717.92 | J13: =IF(OR(G13<=0,I13<=0),0,I13/G13-1) -> 0 | K13: =AW13/1000000 -> 104717.92 | L13: =IF(OR(I13<=0,K13<=0),0,K13/I13-1) -> 0 | M13: =AY13/1000000 -> 83607.415 | N13: =IF(OR(K13<=0,M13<=0),0,M13/K13-1) -> -0.20159402 | O13: =BA13/1000000 -> 83607.415 | P13: =IF(OR(M13<=0,O13<=0),0,O13/M13-1) -> 0 | V13: 자본금 | X13: 32813 | Y13: 0 | Z13: 32813 | AA13: 0 | AB13: 32813 | AC13: 0 | AD13: 32813 | AE13: 0 | AF13: 32813 | AG13: 0 | AI13: =#REF!-X13 -> #REF! | AJ13: =#REF!-Z13 -> #REF! | AK13: =E13-AB13 -> -0.5 | AL13: =G13-AD13 -> 71904.922 | AM13: =I13-AF13 -> 71904.922 | AN13: =(AF13-AD13)/AD13 -> 0 | AO13: =AN13*100 -> 0 | AP13: =AG13-AO13 -> 0 | AR13: 자본금 | AS13: 104717922000 | AT13: =G13*1000000-AS13 -> 0 | AU13: 104717922000 | AV13: =I13*1000000-AU13 -> 0 | AW13: 104717922000 | AX13: =K13*1000000-AW13 -> 0 | AY13: 83607415000 | AZ13: =M13*1000000-AY13 -> 0 | BA13: ='SAP BS'!G3238 -> 83607415000 | BB13: =O13*1000000-BA13 -> 0 | BD13: 1. 자본금 | BE13: 83607415000 | BG13: =BA13-BE13 -> 0
C14: 자본잉여금 | E14: 110531.91 | G14: =AS14/1000000 -> 1195692.5 | H14: =IF(OR(E14<=0,G14<=0),0,G14/E14-1) -> 9.8176226 | I14: =AU14/1000000 -> 1195692.5 | J14: =IF(OR(G14<=0,I14<=0),0,I14/G14-1) -> 0 | K14: =AW14/1000000 -> 1195692.5 | L14: =IF(OR(I14<=0,K14<=0),0,K14/I14-1) -> 0 | M14: =AY14/1000000 -> 966458.25 | N14: =IF(OR(K14<=0,M14<=0),0,M14/K14-1) -> -0.1917167 | O14: =BA14/1000000 -> 966458.25 | P14: =IF(OR(M14<=0,O14<=0),0,O14/M14-1) -> 0 | V14: 자본잉여금 | X14: 79915 | Y14: 0 | Z14: 110532 | AA14: 38.3 | AB14: 110532 | AC14: 0 | AD14: 110532 | AE14: 0 | AF14: 110531 | AG14: 0 | AI14: =#REF!-X14 -> #REF! | AJ14: =#REF!-Z14 -> #REF! | AK14: =E14-AB14 -> -0.092148 | AL14: =G14-AD14 -> 1085160.5 | AM14: =I14-AF14 -> 1085161.5 | AN14: =(AF14-AD14)/AD14 -> -9.0471538e-06 | AO14: =AN14*100 -> -0.00090471538 | AP14: =AG14-AO14 -> 0.00090471538 | AR14: 자본잉여금 | AS14: 1195692464341 | AT14: =G14*1000000-AS14 -> 0 | AU14: 1195692464341 | AV14: =I14*1000000-AU14 -> 0 | AW14: 1195692464341 | AX14: =K14*1000000-AW14 -> 0 | AY14: 966458250863 | AZ14: =M14*1000000-AY14 -> 0 | BA14: ='SAP BS'!G3247 -> 966458250863 | BB14: =O14*1000000-BA14 -> 0 | BD14: 2. 자본잉여금 | BE14: 966458250863 | BG14: =BA14-BE14 -> 0
C15: 기타포괄손익누계액 | E15: 14954.212 | G15: =AS15/1000000 -> 15250.511 | H15: =IF(OR(E15<=0,G15<=0),0,G15/E15-1) -> 0.019813762 | I15: =AU15/1000000 -> 44541.119 | J15: =IF(OR(G15<=0,I15<=0),0,I15/G15-1) -> 1.9206312 | K15: =AW15/1000000 -> 61372.766 | L15: =IF(OR(I15<=0,K15<=0),0,K15/I15-1) -> 0.37789008 | M15: =AY15/1000000 -> 86173.492 | N15: =IF(OR(K15<=0,M15<=0),0,M15/K15-1) -> 0.40409985 | O15: =BA15/1000000 -> 125770.59 | P15: =IF(OR(M15<=0,O15<=0),0,O15/M15-1) -> 0.45950438 | V15: 기타포괄손익누계액 | X15: 21496 | Y15: 29.1 | Z15: 18404 | AA15: -14.4 | AB15: 195 | AC15: -98.9 | AD15: 66 | AE15: -66.3 | AF15: 14954 | AG15: 22631.5 | AI15: =#REF!-X15 -> #REF! | AJ15: =#REF!-Z15 -> #REF! | AK15: =E15-AB15 -> 14759.212 | AL15: =G15-AD15 -> 15184.511 | AM15: =I15-AF15 -> 29587.119 | AN15: =(AF15-AD15)/AD15 -> 225.57576 | AO15: =AN15*100 -> 22557.576 | AP15: =AG15-AO15 -> 73.924242 | AR15: 기타포괄손익누계액 | AS15: 15250511104 | AT15: =G15*1000000-AS15 -> 0 | AU15: 44541119291 | AV15: =I15*1000000-AU15 -> 0 | AW15: 61372766389 | AX15: =K15*1000000-AW15 -> 0 | AY15: 86173492346 | AZ15: =M15*1000000-AY15 -> 0 | BA15: ='SAP BS'!G3272 -> 125770589507 | BB15: =O15*1000000-BA15 -> 0 | BD15: 4. 기타포괄손익누계액 | BE15: 125770589507 | BG15: =BA15-BE15 -> 0
C16: 이익잉여금 | E16: 1199178.8 | G16: =AS16/1000000 -> 2893795.2 | H16: =IF(OR(E16<=0,G16<=0),0,G16/E16-1) -> 1.4131474 | I16: =AU16/1000000 -> 2863022.2 | J16: =IF(OR(G16<=0,I16<=0),0,I16/G16-1) -> -0.010634151 | K16: =AW16/1000000 -> 2788933.1 | L16: =IF(OR(I16<=0,K16<=0),0,K16/I16-1) -> -0.025877909 | M16: =AY16/1000000 -> 2667658.8 | N16: =IF(OR(K16<=0,M16<=0),0,M16/K16-1) -> -0.043484117 | O16: =BA16/1000000 -> 2750737.4 | P16: =IF(OR(M16<=0,O16<=0),0,O16/M16-1) -> 0.031142877 | V16: 이익잉여금 | X16: 912971 | Y16: 8.7 | Z16: 967275 | AA16: 5.9 | AB16: 1046486 | AC16: 8.2 | AD16: 1109958 | AE16: 6.1 | AF16: 1199179 | AG16: 8 | AI16: =#REF!-X16 -> #REF! | AJ16: =#REF!-Z16 -> #REF! | AK16: =E16-AB16 -> 152692.81 | AL16: =G16-AD16 -> 1783837.2 | AM16: =I16-AF16 -> 1663843.2 | AN16: =(AF16-AD16)/AD16 -> 0.080382321 | AO16: =AN16*100 -> 8.0382321 | AP16: =AG16-AO16 -> -0.038232077 | AR16: 이익잉여금(결손금) | AS16: 2893795221644 | AT16: =G16*1000000-AS16 -> 0 | AU16: 2863022166155 | AV16: =I16*1000000-AU16 -> 0 | AW16: 2788933138348 | AX16: =K16*1000000-AW16 -> 0 | AY16: 2667658844231 | AZ16: =M16*1000000-AY16 -> 0 | BA16: ='SAP BS'!G3291 -> 2750737415521 | BB16: =O16*1000000-BA16 -> 0 | BD16: 5. 이익잉여금 | BE16: 2750737415521 | BG16: =BA16-BE16 -> 0
C17: 기타자본항목 | E17: -108729.69 | G17: =AS17/1000000 -> -98183.617 | H17: =(G17-E17)/E17 -> -0.096993525 | I17: =AU17/1000000 -> -98183.617 | J17: =(I17-G17)/G17 -> 0 | K17: =AW17/1000000 -> -68183.615 | L17: =(K17-I17)/I17 -> -0.30554998 | M17: =AY17/1000000 -> -601533.95 | N17: =(M17-K17)/K17 -> 7.8222654 | O17: =BA17/1000000 -> -601533.95 | P17: =(O17-M17)/M17 -> 0 | Q17: `23년 자기주식 처분, `24년 파르나스호텔 분할 | V17: 자본조정 | X17: -55622 | Y17: 51 | Z17: -45871 | AA17: -17.5 | AB17: -96870 | AC17: 111.2 | AD17: -108109 | AE17: 11.6 | AF17: -108730 | AG17: 0.6 | AI17: =#REF!-X17 -> #REF! | AJ17: =#REF!-Z17 -> #REF! | AK17: =E17-AB17 -> -11859.693 | AL17: =G17-AD17 -> 9925.383 | AM17: =I17-AF17 -> 10546.383 | AN17: =(AF17-AD17)/AD17 -> 0.0057442026 | AO17: =AN17*100 -> 0.57442026 | AP17: =AG17-AO17 -> 0.025579739 | AR17: 기타자본구성요소 | AS17: -98183617004 | AT17: =G17*1000000-AS17 -> 0 | AU17: -98183617004 | AV17: =I17*1000000-AU17 -> 0 | AW17: -68183615271 | AX17: =K17*1000000-AW17 -> 0 | AY17: -601533949972 | AZ17: =M17*1000000-AY17 -> 0 | BA17: ='SAP BS'!G3258 -> -601533949972 | BB17: =O17*1000000-BA17 -> 0 | BD17: 3. 기타자본항목 | BE17: -601533949972 | BG17: =BA17-BE17 -> 0
A18: 요약손익계산서 | B18: 매출액 | E18: 1206716.4 | G18: =AS18/1000000 -> 9118512.6 | H18: =IF(OR(E18<=0,G18<=0),0,G18/E18-1) -> 6.5564668 | I18: =AU18/1000000 -> 10409711 | J18: =IF(OR(G18<=0,I18<=0),0,I18/G18-1) -> 0.14160189 | K18: =AW18/1000000 -> 10886895 | L18: =IF(OR(I18<=0,K18<=0),0,K18/I18-1) -> 0.04584022 | M18: =AY18/1000000 -> 11378032 | N18: =IF(OR(K18<=0,M18<=0),0,M18/K18-1) -> 0.045112713 | O18: =BA18/1000000 -> 11774644 | P18: =IF(OR(M18<=0,O18<=0),0,O18/M18-1) -> 0.034857683 | T18: 요약 | U18: 매출액 | X18: 1065156 | Y18: -2.4 | Z18: 1051658 | AA18: -1.3 | AB18: 1073514 | AC18: 2.1 | AD18: 1194600 | AE18: 11.3 | AF18: 1206717 | AG18: 1 | AI18: =#REF!-X18 -> #REF! | AJ18: =#REF!-Z18 -> #REF! | AK18: =E18-AB18 -> 133202.43 | AL18: =G18-AD18 -> 7923912.6 | AM18: =I18-AF18 -> 9202994.2 | AN18: =(AF18-AD18)/AD18 -> 0.010143144 | AO18: =AN18*100 -> 1.0143144 | AP18: =AG18-AO18 -> -0.014314415 | AR18: 매출액 | AS18: 9118512626842 | AU18: 10409711225602 | AW18: 10886894680059 | AY18: 11378032037656 | BA18: ='12. 추정 IS'!AZ19*1000 -> 11774643877003 | BB18: =O18*1000000-BA18 -> 0 | BE18: 11774643877003 | BG18: =BA18-BE18 -> 0
C19: [1] 홈쇼핑부문 | E19: =SUM(E20:E22) -> 1206716.4 | G19: =SUM(G20:G22) -> 1227065 | H19: =IF(OR(E19<=0,G19<=0),0,G19/E19-1) -> 0.016862763 | I19: =SUM(I20:I22) -> 1239315 | J19: =IF(OR(G19<=0,I19<=0),0,I19/G19-1) -> 0.0099831712 | K19: =SUM(K20:K22) -> 1131065.4 | L19: =IF(OR(I19<=0,K19<=0),0,K19/I19-1) -> -0.087346322 | M19: =SUM(M20:M22) -> 1052079.3 | N19: =IF(OR(K19<=0,M19<=0),0,M19/K19-1) -> -0.069833318 | O19: =SUM(O20:O22) -> 1049110.2 | P19: =IF(OR(M19<=0,O19<=0),0,O19/M19-1) -> -0.0028221786
C20: (방송사업매출액) | E20: 368468 | G20: ='9. 추정 IS'!F37+'9. 추정 IS'!F38 -> 370055 | H20: =(G20-E20)/E20 -> 0.0043070226 | I20: ='9. 추정 IS'!G37+'9. 추정 IS'!G38 -> 367350 | J20: =(I20-G20)/G20 -> -0.0073097242 | K20: ='9. 추정 IS'!H37+'9. 추정 IS'!H38 -> 346760.93 | L20: =(K20-I20)/I20 -> -0.056047564 | M20: ='9. 추정 IS'!I37+'9. 추정 IS'!I38 -> 311281.54 | N20: =(M20-K20)/K20 -> -0.10231656 | O20: ='9. 추정 IS'!J37+'9. 추정 IS'!J38 -> 333966.8 | P20: =IF(OR(M20<=0,O20<=0),0,O20/M20-1) -> 0.072876976 | Q20: 데이터홈쇼핑 및 TV홈쇼핑 수수료매출, 광고매출 | T20: 손익 | V20: 방송사업매출액 | X20: 576892 | Y20: -4.7 | Z20: 581503 | AA20: 0.8 | AB20: 494945 | AC20: -14.9 | AD20: 378770 | AE20: -23.5 | AF20: 368468 | AG20: -2.7 | AI20: =#REF!-X20 -> #REF! | AJ20: =#REF!-Z20 -> #REF! | AK20: =E20-AB20 -> -126477 | AL20: =G20-AD20 -> -8715 | AM20: =I20-AF20 -> -1118 | AN20: =(AF20-AD20)/AD20 -> -0.027198564 | AO20: =AN20*100 -> -2.7198564 | AP20: =AG20-AO20 -> 0.019856377
C21: (방송상품매출액) | E21: 105296 | G21: ='9. 추정 IS'!F31+'9. 추정 IS'!F32 -> 97040 | H21: =(G21-E21)/E21 -> -0.078407537 | I21: ='9. 추정 IS'!G31+'9. 추정 IS'!G32 -> 106344 | J21: =(I21-G21)/G21 -> 0.095877988 | K21: ='9. 추정 IS'!H31+'9. 추정 IS'!H32 -> 89694.981 | L21: =(K21-I21)/I21 -> -0.15655814 | M21: ='9. 추정 IS'!I31+'9. 추정 IS'!I32 -> 76110.235 | N21: =(M21-K21)/K21 -> -0.15145492 | O21: ='9. 추정 IS'!J31+'9. 추정 IS'!J32 -> 84255.337 | P21: =IF(OR(M21<=0,O21<=0),0,O21/M21-1) -> 0.10701718 | Q21: 데이터홈쇼핑 및 TV홈쇼핑 상품매출(직매입) | T21: 계산서 | V21: 방송상품매출액 | X21: 72039 | Y21: 12.4 | Z21: 49666 | AA21: -31.1 | AB21: 69393 | AC21: 39.7 | AD21: 143640 | AE21: 107 | AF21: 105296 | AG21: -26.7 | AI21: =#REF!-X21 -> #REF! | AJ21: =#REF!-Z21 -> #REF! | AK21: =E21-AB21 -> 35903 | AL21: =G21-AD21 -> -46600 | AM21: =I21-AF21 -> 1048 | AN21: =(AF21-AD21)/AD21 -> -0.26694514 | AO21: =AN21*100 -> -26.694514 | AP21: =AG21-AO21 -> -0.0054859371
C22: (기타사업매출액) | E22: =SUM(E23:E25) -> 732952.43 | G22: =SUM(G23:G25) -> 759970 | H22: =IF(OR(E22<=0,G22<=0),0,G22/E22-1) -> 0.036861292 | I22: =SUM(I23:I25) -> 765621 | J22: =IF(OR(G22<=0,I22<=0),0,I22/G22-1) -> 0.0074358198 | K22: =SUM(K23:K25) -> 694609.48 | L22: =IF(OR(I22<=0,K22<=0),0,K22/I22-1) -> -0.092750219 | M22: =SUM(M23:M25) -> 664687.57 | N22: =IF(OR(K22<=0,M22<=0),0,M22/K22-1) -> -0.043077326 | O22: =SUM(O23:O25) -> 630888.05 | P22: =IF(OR(M22<=0,O22<=0),0,O22/M22-1) -> -0.050850231 | V22: 기타사업매출액 | X22: 416225 | Y22: -1.3 | Z22: 420489 | AA22: 1 | AB22: 509176 | AC22: 21.1 | AD22: 672190 | AE22: 32 | AF22: 732953 | AG22: 9 | AI22: =#REF!-X22 -> #REF! | AJ22: =#REF!-Z22 -> #REF! | AK22: =E22-AB22 -> 223776.43 | AL22: =G22-AD22 -> 87780 | AM22: =I22-AF22 -> 32668 | AN22: =(AF22-AD22)/AD22 -> 0.090395573 | AO22: =AN22*100 -> 9.0395573 | AP22: =AG22-AO22 -> -0.039557268
D23: [카탈로그매출액] | E23: 0 | G23: ='9. 추정 IS'!F28 -> 0 | H23: 0 | I23: ='9. 추정 IS'!G28 -> 0 | J23: 0 | K23: ='9. 추정 IS'!H28 -> 0 | L23: 0 | M23: ='9. 추정 IS'!I28 -> 0 | N23: 0 | O23: ='9. 추정 IS'!J28 -> 0 | P23: =IF(OR(M23<=0,O23<=0),0,O23/M23-1) -> 0 | W23: 카탈로그매출액 | X23: 27288 | Y23: -22.1 | Z23: 22721 | AA23: -16.7 | AB23: 20728 | AC23: -8.8 | AD23: 9057 | AE23: -56.3 | AF23: 0 | AG23: -100 | AI23: =#REF!-X23 -> #REF! | AJ23: =#REF!-Z23 -> #REF! | AK23: =E23-AB23 -> -20728 | AL23: =G23-AD23 -> -9057 | AM23: =I23-AF23 -> 0 | AN23: =(AF23-AD23)/AD23 -> -1 | AO23: =AN23*100 -> -100 | AP23: =AG23-AO23 -> 0 | BD23: (단위 : 원) | BE23: 2021 | BG23: 2022 | BI23: 2023
D24: [모바일인터넷매출액] | E24: =688859-0.573183000087738 -> 688858.43 | G24: ='9. 추정 IS'!F27 -> 723367 | H24: =(G24-E24)/E24 -> 0.050095305 | I24: ='9. 추정 IS'!G27 -> 732689 | J24: =(I24-G24)/G24 -> 0.012886958 | K24: ='9. 추정 IS'!H27 -> 675496.46 | L24: =(K24-I24)/I24 -> -0.078058419 | M24: ='9. 추정 IS'!I27 -> 648115.45 | N24: =(M24-K24)/K24 -> -0.040534633 | O24: ='9. 추정 IS'!J27 -> 611356.65 | P24: =IF(OR(M24<=0,O24<=0),0,O24/M24-1) -> -0.056716451 | W24: 모바일인터넷매출액 | X24: 350992 | Y24: 3.6 | Z24: 363072 | AA24: 3.4 | AB24: 451059 | AC24: 24.2 | AD24: 619019 | AE24: 37.2 | AF24: 688859 | AG24: 11.3 | AI24: =#REF!-X24 -> #REF! | AJ24: =#REF!-Z24 -> #REF! | AK24: =E24-AB24 -> 237799.43 | AL24: =G24-AD24 -> 104348 | AM24: =I24-AF24 -> 43830 | AN24: =(AF24-AD24)/AD24 -> 0.11282368 | AO24: =AN24*100 -> 11.282368 | AP24: =AG24-AO24 -> 0.017632254 | BE24: 제 52 기 | BG24: 제 53 기 | BI24: 제 54 기
D25: [기타매출액] | E25: 44094 | G25: ='9. 추정 IS'!F29 -> 36603 | H25: =(G25-E25)/E25 -> -0.16988706 | I25: ='9. 추정 IS'!G29 -> 32932 | J25: =(I25-G25)/G25 -> -0.10029233 | K25: ='9. 추정 IS'!H29 -> 19113.03 | L25: =(K25-I25)/I25 -> -0.41962136 | M25: ='9. 추정 IS'!I29 -> 16572.112 | N25: =(M25-K25)/K25 -> -0.13294167 | O25: ='9. 추정 IS'!J29 -> 19531.404 | P25: =IF(OR(M25<=0,O25<=0),0,O25/M25-1) -> 0.17857062 | W25: 기타매출액 | X25: 37945 | Y25: -21 | Z25: 34696 | AA25: -8.6 | AB25: 37389 | AC25: 7.8 | AD25: 44113 | AE25: 18 | AF25: 44093 | AG25: 0 | AI25: =#REF!-X25 -> #REF! | AJ25: =#REF!-Z25 -> #REF! | AK25: =E25-AB25 -> 6705 | AL25: =G25-AD25 -> -7510 | AM25: =I25-AF25 -> -11161 | AN25: =(AF25-AD25)/AD25 -> -0.00045338109 | AO25: =AN25*100 -> -0.045338109 | AP25: =AG25-AO25 -> 0.045338109 | BD25: 매출액 | BE25: 9118512626842 | BG25: 10409711225602 | BI25: 10886894680059 | BK25: =BE25-AS18 -> 0 | BM25: =BG25-AU18 -> 0 | BO25: =BI25-AW18 -> 0
C26: [2] 리테일부문 | E26: =E18-E19 -> 0 | G26: =G18-G19 -> 7891447.6 | H26: =IF(OR(E26<=0,G26<=0),0,G26/E26-1) -> 0 | I26: =I18-I19 -> 9170396.2 | J26: =IF(OR(G26<=0,I26<=0),0,I26/G26-1) -> 0.16206768 | K26: =K18-K19 -> 9755829.3 | L26: =IF(OR(I26<=0,K26<=0),0,K26/I26-1) -> 0.063839451 | M26: =M18-M19 -> 10325953 | N26: =IF(OR(K26<=0,M26<=0),0,M26/K26-1) -> 0.058439256 | O26: =O18-O19 -> 10725534 | P26: =IF(OR(M26<=0,O26<=0),0,O26/M26-1) -> 0.038696768
B27: 매출원가 | E27: =E28 -> 323447.55 | G27: =-AS27/1000000 -> 6983785.4 | H27: =(G27-E27)/E27 -> 20.591709 | I27: =-AU27/1000000 -> 7684960.9 | J27: =(I27-G27)/G27 -> 0.10040049 | K27: =-AW27/1000000 -> 8092649.9 | L27: =(K27-I27)/I27 -> 0.053050237 | M27: =-AY27/1000000 -> 8539950.4 | N27: =(M27-K27)/K27 -> 0.055272443 | O27: =-BA27/1000000 -> 8902467.3 | P27: =(O27-M27)/M27 -> 0.042449535 | U27: 매출원가 | X27: 94279 | Y27: -15.2 | Z27: 69105 | AA27: -26.7 | AB27: 253228 | AC27: 266.4 | AD27: 371296 | AE27: 46.6 | AF27: 200911 | AG27: -45.9 | AI27: =#REF!-X27 -> #REF! | AJ27: =#REF!-Z27 -> #REF! | AK27: =E27-AB27 -> 70219.547 | AL27: =G27-AD27 -> 6612489.4 | AM27: =I27-AF27 -> 7484049.9 | AN27: =(AF27-AD27)/AD27 -> -0.45889264 | AO27: =AN27*100 -> -45.889264 | AP27: =AG27-AO27 -> -0.010736447 | AR27: 매출원가 | AS27: -6983785409167 | AU27: -7684960869850 | AW27: -8092649867644 | AY27: -8539950394843 | BA27: =-'12. 추정 IS'!AZ30*1000 -> -8902467317440 | BB27: =O27*1000000+BA27 -> 0 | BD27: 매출원가 | BE27: -6983785409167 | BG27: -7684960869850 | BI27: -8092649867644 | BK27: =BE27-AS27 -> 0 | BM27: =BG27-AU27 -> 0 | BO27: =BI27-AW27 -> 0
C28: [1] 홈쇼핑부문 | E28: 323447.55 | G28: ='9. 추정 IS'!F43 -> 192258 | H28: =(G28-E28)/E28 -> -0.40559759 | I28: ='9. 추정 IS'!G43 -> 187896 | J28: =(I28-G28)/G28 -> -0.022688263 | K28: ='9. 추정 IS'!H43 -> 149269 | L28: =(K28-I28)/I28 -> -0.20557649 | M28: ='9. 추정 IS'!I43 -> 119598 | N28: =(M28-K28)/K28 -> -0.19877537 | O28: ='9. 추정 IS'!J43 -> 139480.35 | P28: =(O28-M28)/M28 -> 0.16624314 | U28: 매출총이익 | X28: 970877 | Y28: -1 | Z28: 982553 | AA28: 1.2 | AB28: 820286 | AC28: -16.5 | AD28: 823304 | AE28: 0.4 | AF28: 1005806 | AG28: 22.2 | AI28: =#REF!-X28 -> #REF! | AJ28: =#REF!-Z28 -> #REF! | AK28: =E28-AB28 -> -496838.45 | AL28: =G28-AD28 -> -631046 | AM28: =I28-AF28 -> -817910 | AN28: =(AF28-AD28)/AD28 -> 0.22167025 | AO28: =AN28*100 -> 22.167025 | AP28: =AG28-AO28 -> 0.032975426
C29: [2] 리테일부문 | E29: =E27-E28 -> 0 | G29: =G27-G28 -> 6791527.4 | H29: =IF(OR(E29<=0,G29<=0),0,G29/E29-1) -> 0 | I29: =I27-I28 -> 7497064.9 | J29: =IF(OR(G29<=0,I29<=0),0,I29/G29-1) -> 0.10388495 | K29: =K27-K28 -> 7943380.9 | L29: =IF(OR(I29<=0,K29<=0),0,K29/I29-1) -> 0.059532098 | M29: =M27-M28 -> 8420352.4 | N29: =IF(OR(K29<=0,M29<=0),0,M29/K29-1) -> 0.060046413 | O29: =O27-O28 -> 8762987 | P29: =IF(OR(M29<=0,O29<=0),0,O29/M29-1) -> 0.040691239
B30: 매출총이익 | E30: =E18-E27 -> 883268.88 | G30: =G18-G27 -> 2134727.2 | H30: =IF(OR(E30<=0,G30<=0),0,G30/E30-1) -> 1.4168487 | I30: =I18-I27 -> 2724750.4 | J30: =IF(OR(G30<=0,I30<=0),0,I30/G30-1) -> 0.27639276 | K30: =K18-K27 -> 2794244.8 | L30: =IF(OR(I30<=0,K30<=0),0,K30/I30-1) -> 0.025504889 | M30: =M18-M27 -> 2838081.6 | N30: =IF(OR(K30<=0,M30<=0),0,M30/K30-1) -> 0.015688257 | O30: =O18-O27 -> 2872176.6 | P30: =IF(OR(M30<=0,O30<=0),0,O30/M30-1) -> 0.012013367 | AR30: 매출총이익 | AS30: 2134727217675 | AT30: =AS30-G30*1000000 -> 0 | AU30: 2724750355752 | AV30: =AU30-I30*1000000 -> 0 | AW30: 2794244812415 | AX30: =AW30-K30*1000000 -> 0 | AY30: 2838081642813 | AZ30: =AY30-M30*1000000 -> 0 | BA30: ='12. 추정 IS'!AZ40*1000 -> 2.8721766e+12 | BB30: =BA30-O30*1000000 -> 0 | BD30: 매출총이익 | BE30: 2134727217675 | BG30: 2724750355752 | BI30: 2794244812415 | BK30: =BE30-AS30 -> 0 | BM30: =BG30-AU30 -> 0 | BO30: =BI30-AW30 -> 0
B31: 판매비와관리비 | E31: =E32 -> 725384.46 | G31: =-AS31/1000000 -> 1829758.9 | H31: =(G31-E31)/E31 -> 1.5224677 | I31: =-AU31/1000000 -> 2357696.6 | J31: =(I31-G31)/G31 -> 0.28852855 | K31: =-AW31/1000000 -> 2479262.8 | L31: =(K31-I31)/I31 -> 0.051561444 | M31: =-AY31/1000000 -> 2585445.8 | N31: =(M31-K31)/K31 -> 0.042828437 | O31: =-BA31/1000000 -> 2582279.8 | P31: =IF(OR(M31<=0,O31<=0),0,O31/M31-1) -> -0.0012245147 | Q31: 매출채권및기타채권 손상차손(환입) 금액 포함 합산표시 | U31: 판매비와관리비 | X31: 842246 | Y31: -2.9 | Z31: 838063 | AA31: -0.5 | AB31: 682949 | AC31: -18.5 | AD31: 703254 | AE31: 3 | AF31: 847921 | AG31: 20.6 | AI31: =#REF!-X31 -> #REF! | AJ31: =#REF!-Z31 -> #REF! | AK31: =E31-AB31 -> 42435.46 | AL31: =G31-AD31 -> 1126504.9 | AM31: =I31-AF31 -> 1509775.6 | AN31: =(AF31-AD31)/AD31 -> 0.20571088 | AO31: =AN31*100 -> 20.571088 | AP31: =AG31-AO31 -> 0.028911887 | AR31: 판매비와관리비 | AS31: -1829758885953 | AU31: -2357696565226 | AW31: -2479262805686 | AY31: -2585445756334 | BA31: =-'12. 추정 IS'!AZ41*1000 -> -2.5822798e+12 | BB31: =O31*1000000+BA31 -> 0 | BE31: =SUM(BE32:BE33) -> -1829758885953 | BG31: -2357696565226 | BI31: -2479262805686 | BK31: =BE31-AS31 -> 0 | BM31: =BG31-AU31 -> 0 | BO31: =BI31-AW31 -> 0
C32: [1] 홈쇼핑부문 | E32: 725384.46 | G32: ='9. 추정 IS'!F48 -> 898893 | H32: =(G32-E32)/E32 -> 0.23919528 | I32: ='9. 추정 IS'!G48 -> 908849 | J32: =(I32-G32)/G32 -> 0.011075846 | K32: ='9. 추정 IS'!H48 -> 864887.02 | L32: =(K32-I32)/I32 -> -0.048371053 | M32: ='9. 추정 IS'!I48 -> 825389.02 | N32: =(M32-K32)/K32 -> -0.045668392 | O32: ='9. 추정 IS'!J48 -> 816617.22 | P32: =IF(OR(M32<=0,O32<=0),0,O32/M32-1) -> -0.010627469 | BD32: 판매비와관리비 | BE32: -1829334017070 | BG32: -2356369136594 | BI32: -2459851579944
C33: (홈쇼핑부문 인건비) | E33: 104642 | G33: ='9. 추정 IS'!F50 -> 108194 | H33: =(G33-E33)/E33 -> 0.033944305 | I33: ='9. 추정 IS'!G50 -> 74094 | J33: =(I33-G33)/G33 -> -0.31517459 | K33: ='9. 추정 IS'!H50 -> 82590 | L33: =(K33-I33)/I33 -> 0.11466516 | M33: ='9. 추정 IS'!I50 -> 84194 | N33: =(M33-K33)/K33 -> 0.019421237 | O33: ='9. 추정 IS'!J50 -> 85905.775 | P33: =IF(OR(M33<=0,O33<=0),0,O33/M33-1) -> 0.020331318 | V33: 인건비 | X33: 102606 | Y33: 8.1 | Z33: 97219 | AA33: -5.3 | AB33: 96305 | AC33: -0.9 | AD33: 106070 | AE33: 10.1 | AF33: 104642 | AG33: -1.3 | AI33: =#REF!-X33 -> #REF! | AJ33: =#REF!-Z33 -> #REF! | AK33: =E33-AB33 -> 8337 | AL33: =G33-AD33 -> 2124 | AM33: =I33-AF33 -> -30548 | AN33: =(AF33-AD33)/AD33 -> -0.013462808 | AO33: =AN33*100 -> -1.3462808 | AP33: =AG33-AO33 -> 0.046280758 | BD33: 매출채권및기타채권 등 손상차손 | BE33: -424868883 | BG33: -1327428632 | BI33: -19411225742
C34: [2] 리테일부문 | E34: 0 | G34: =G31-G32 -> 930865.89 | H34: =IF(OR(E34<=0,G34<=0),0,G34/E34-1) -> 0 | I34: =I31-I32 -> 1448847.6 | J34: =IF(OR(G34<=0,I34<=0),0,I34/G34-1) -> 0.55645146 | K34: =K31-K32 -> 1614375.8 | L34: =IF(OR(I34<=0,K34<=0),0,K34/I34-1) -> 0.1142482 | M34: =M31-M32 -> 1760056.7 | N34: =IF(OR(K34<=0,M34<=0),0,M34/K34-1) -> 0.090239801 | O34: =O31-O32 -> 1765662.6 | P34: =IF(OR(M34<=0,O34<=0),0,O34/M34-1) -> 0.0031850564
B35: 영업손익 | E35: =E30-E31 -> 157884.42 | G35: =G30-G31 -> 304968.33 | H35: =IF(OR(E35<=0,G35<=0),0,G35/E35-1) -> 0.93159231 | I35: =I30-I31 -> 367053.79 | J35: =IF(OR(G35<=0,I35<=0),0,I35/G35-1) -> 0.20358002 | K35: =K30-K31 -> 314982.01 | L35: =IF(OR(I35<=0,K35<=0),0,K35/I35-1) -> -0.14186418 | M35: =M30-M31 -> 252635.89 | N35: =IF(OR(K35<=0,M35<=0),0,M35/K35-1) -> -0.1979355 | O35: =O30-O31 -> 289896.72 | P35: =IF(OR(M35<=0,O35<=0),0,O35/M35-1) -> 0.14748828 | U35: 영업손익 | X35: 128631 | Y35: 14.4 | Z35: 144490 | AA35: 12.3 | AB35: 137337 | AC35: -5 | AD35: 120050 | AE35: -12.6 | AF35: 157885 | AG35: 31.5 | AI35: =#REF!-X35 -> #REF! | AJ35: =#REF!-Z35 -> #REF! | AK35: =E35-AB35 -> 20547.42 | AL35: =G35-AD35 -> 184918.33 | AM35: =I35-AF35 -> 209168.79 | AN35: =(AF35-AD35)/AD35 -> 0.31516035 | AO35: =AN35*100 -> 31.516035 | AP35: =AG35-AO35 -> -0.016034985 | AR35: 영업이익(손실) | AS35: 304968331722 | AT35: =AS35-G35*1000000 -> 0.00054931641 | AU35: 367053790526 | AV35: =AU35-I35*1000000 -> 0.0010986328 | AW35: 314982006729 | AX35: =AW35-K35*1000000 -> -0.001159668 | AY35: 252635886479 | AZ35: =AY35-M35*1000000 -> 0.00082397461 | BA35: ='12. 추정 IS'!AZ84*1000 -> 2.8989672e+11 | BB35: =BA35-O35*1000000 -> 0 | BD35: 영업이익(손실) | BE35: 304968331722 | BG35: 367053790526 | BI35: 314982006729 | BK35: =BE35-AS35 -> 0 | BM35: =BG35-AU35 -> 0 | BO35: =BI35-AW35 -> 0
C36: [1] 홈쇼핑부문 | E36: =E19-E28-E32 -> 157884.42 | G36: =G19-G28-G32 -> 135914 | H36: =IF(OR(E36<=0,G36<=0),0,G36/E36-1) -> -0.13915509 | I36: =I19-I28-I32 -> 142570 | J36: =IF(OR(G36<=0,I36<=0),0,I36/G36-1) -> 0.048972144 | K36: =K19-K28-K32 -> 116909.38 | L36: =IF(OR(I36<=0,K36<=0),0,K36/I36-1) -> -0.17998614 | M36: =M19-M28-M32 -> 107092.33 | N36: =IF(OR(K36<=0,M36<=0),0,M36/K36-1) -> -0.083971456 | O36: =O19-O28-O32 -> 93012.619 | P36: =IF(OR(M36<=0,O36<=0),0,O36/M36-1) -> -0.13147261
C37: [2] 리테일부문 | E37: =E35-E36 -> 0 | G37: =G35-G36 -> 169054.33 | H37: =IF(OR(E37<=0,G37<=0),0,G37/E37-1) -> 0 | I37: =I35-I36 -> 224483.79 | J37: =IF(OR(G37<=0,I37<=0),0,I37/G37-1) -> 0.32787955 | K37: =K35-K36 -> 198072.63 | L37: =IF(OR(I37<=0,K37<=0),0,K37/I37-1) -> -0.11765286 | M37: =M35-M36 -> 145543.56 | N37: =IF(OR(K37<=0,M37<=0),0,M37/K37-1) -> -0.26520105 | O37: =O35-O36 -> 196884.1 | P37: =IF(OR(M37<=0,O37<=0),0,O37/M37-1) -> 0.35275034
B38: 당기순손익 | E38: 128898.51 | G38: =AS38/1000000 -> 849216.33 | H38: =(G38-E38)/E38 -> 5.5882555 | I38: =AU38/1000000 -> 61514.258 | J38: =(I38-G38)/G38 -> -0.9275635 | K38: =AW38/1000000 -> -24548.413 | L38: =(K38-I38)/I38 -> -1.3990687 | M38: =AY38/1000000 -> -60803.458 | N38: =(M38-K38)/K38 -> 1.4768794 | O38: =BA38/1000000 -> 84116.793 | P38: =(O38-M38)/M38 -> -2.3834212 | U38: 당기순손익 | X38: 103493 | Y38: 28.1 | Z38: 97005 | AA38: -6.3 | AB38: 120615 | AC38: 24.3 | AD38: 106603 | AE38: -11.6 | AF38: 128898 | AG38: 20.9 | AI38: =#REF!-X38 -> #REF! | AJ38: =#REF!-Z38 -> #REF! | AK38: =E38-AB38 -> 8283.5124 | AL38: =G38-AD38 -> 742613.33 | AM38: =I38-AF38 -> -67383.742 | AN38: =(AF38-AD38)/AD38 -> 0.20914046 | AO38: =AN38*100 -> 20.914046 | AP38: =AG38-AO38 -> -0.014045571 | AR38: 당기순이익(손실) | AS38: 849216327484 | AU38: 61514258324 | AW38: -24548412726 | AY38: -60803458305 | BA38: ='12. 추정 IS'!AZ111*1000 -> 8.4116793e+10 | BB38: =BA38-O38*1000000 -> 0 | BD38: 당기순이익(손실) | BE38: 849216327484 | BG38: 61514258324 | BI38: -24548412726 | BK38: =BE38-AS38 -> 0 | BM38: =BG38-AU38 -> 0 | BO38: =BI38-AW38 -> 0
A39: 재무비율 | B39: 유동비율 | E39: =IF(E10<=0,"N/A",E7/E10) -> 2.5954609 | G39: =IF(G10<=0,"N/A",G7/G10) -> 0.60894806 | I39: =IF(I10<=0,"N/A",I7/I10) -> 0.70637636 | K39: =IF(K10<=0,"N/A",K7/K10) -> 0.82632987 | M39: =IF(M10<=0,"N/A",M7/M10) -> 0.81364884 | O39: =IF(O10<=0,"N/A",O7/O10) -> 0.96733882 | Q39: 유동자산/유동부채
B40: 부채비율 | E40: =IF(E12<=0,"N/A",E9/E12) -> 0.25054514 | G40: =IF(G12<=0,"N/A",G9/G12) -> 0.86777458 | I40: =IF(I12<=0,"N/A",I9/I12) -> 0.9347282 | K40: =IF(K12<=0,"N/A",K9/K12) -> 1.0131433 | M40: =IF(M12<=0,"N/A",M9/M12) -> 1.2344588 | O40: =IF(O12<=0,"N/A",O9/O12) -> 1.1417299 | Q40: 부채총계/자본총계
...

Sheet 2. 추정_요약재무제표
A2: ■ 추정 요약 재무제표
U3: (단위 : 백만원)
A4: 구 분 | E4: 2025년 | G4: 2026년 | I4: 2027년 | K4: 2028년 | M4: 2029년 | O4: 2030년 | Q4: 2031년 | S4: 2032년 | U4: 비 고 | AI4: 구 분 | AM4: 2021 | AO4: 2022 | AQ4: 2023 | AS4: 2024 | AU4: 2025
F5: 증감률 | H5: 증감률 | J5: 증감률 | L5: 증감률 | N5: 증감률 | P5: 증감률 | R5: 증감률 | T5: 증감률 | W5: ='7-1. FS'!AD4 -> 2022 | X5: ='7-1. FS'!AE4 -> 2023 | Y5: ='7-1. FS'!AF4 -> 2024 | Z5: ='7-1. FS'!AG4 -> 2025 | AA5: ='7-1. FS'!AH4 -> 2026 | AB5: ='7-1. FS'!AI4 -> 2027 | AC5: ='7-1. FS'!AJ4 -> 2028 | AD5: ='7-1. FS'!AK4 -> 2029 | ... AG5: ='7-1. FS'!AN4 -> 2032 | AM5: 금액 | AN5: 증감률 | AO5: 금액 | AP5: 증감률 | AQ5: 금액 | AR5: 증감률 | AS5: 금액 | AT5: 증감률 | AU5: 금액 | AV5: 증감률
A6: 요약재무상태표 | B6: 자산총계 | E6: =SUM(E7:E8) -> 7121336.9 | G6: =SUM(G7:G8) -> 7099210.7 | H6: =(G6-E6)/E6 -> -0.003107023 | I6: =SUM(I7:I8) -> 7163823.6 | J6: =(I6-G6)/G6 -> 0.0091014196 | K6: =SUM(K7:K8) -> 7227078.5 | L6: =(K6-I6)/I6 -> 0.0088297748 | M6: =SUM(M7:M8) -> 7305975.3 | N6: =(M6-K6)/K6 -> 0.01091682 | O6: =SUM(O7:O8) -> 7403329.7 | P6: =(O6-M6)/M6 -> 0.013325316 | Q6: =SUM(Q7:Q8) -> 7507419.1 | R6: =(Q6-O6)/O6 -> 0.01405981 | S6: =SUM(S7:S8) -> 7624408.7 | T6: =(S6-Q6)/Q6 -> 0.0155832 | AI6: 요약 | AJ6: 자산총계 | AM6: 7159001 | AN6: 3.584 | AO6: 7429779 | AP6: 0.038 | AQ6: 7728828 | AR6: 0.04 | AS6: 8214836 | AT6: 0.063 | AU6: 8659410 | AV6: 0.054 | AX6: =#REF!-AM6 -> #REF! | AY6: =#REF!-AO6 -> #REF! | AZ6: =#REF!-AQ6 -> #REF! | BA6: =#REF!-AS6 -> #REF! | BB6: =E6-AU6 -> -1538073.1 | BC6: =(AU6-AS6)/AS6 -> 0.054118427 | BD6: =AV6-BC6 -> -0.00011842671
C7: 유동자산 | E7: ='1. 요약재무제표'!O7 -> 1670299 | G7: =AA7 -> 1730329 | H7: =(G7-E7)/E7 -> 0.035939664 | I7: =AB7 -> 1845752.3 | J7: =(I7-G7)/G7 -> 0.066705994 | K7: =AC7 -> 1948134.1 | L7: =(K7-I7)/I7 -> 0.055468902 | M7: =AD7 -> 1966437.4 | N7: =(M7-K7)/K7 -> 0.0093952775 | O7: =AE7 -> 2000160.3 | P7: =(O7-M7)/M7 -> 0.017149241 | Q7: =AF7 -> 2031732 | R7: =(Q7-O7)/O7 -> 0.015784607 | S7: =AG7 -> 2070270.4 | T7: =(S7-Q7)/Q7 -> 0.018968226 | W7: ='7-1. FS'!AD6 -> 1219865.1 | X7: ='7-1. FS'!AE6 -> 1716831.9 | Y7: ='7-1. FS'!AF6 -> 1422037.5 | Z7: ='7-1. FS'!AG6 -> 1670243.3 | AA7: ='7-1. FS'!AH6 -> 1730329 | AB7: ='7-1. FS'!AI6 -> 1845752.3 | AC7: ='7-1. FS'!AJ6 -> 1948134.1 | AD7: ='7-1. FS'!AK6 -> 1966437.4 | ... AG7: ='7-1. FS'!AN6 -> 2070270.4 | AI7: 재무 | AK7: 유동자산 | AM7: 1801150 | AN7: 1.431 | AO7: 1998924 | AP7: 0.11 | AQ7: 2231671 | AR7: 0.116 | AS7: 2624613 | AT7: 0.176 | AU7: 3108861 | AV7: 0.185 | AX7: =#REF!-AM7 -> #REF! | AY7: =#REF!-AO7 -> #REF! | AZ7: =#REF!-AQ7 -> #REF! | BA7: =#REF!-AS7 -> #REF! | BB7: =E7-AU7 -> -1438562 | BC7: =(AU7-AS7)/AS7 -> 0.18450263 | BD7: =AV7-BC7 -> 0.00049737047
C8: 비유동자산 | E8: ='1. 요약재무제표'!O8 -> 5451037.9 | G8: =AA8 -> 5368881.7 | H8: =(G8-E8)/E8 -> -0.015071651 | I8: =AB8 -> 5318071.3 | J8: =(I8-G8)/G8 -> -0.0094638733 | K8: =AC8 -> 5278944.4 | L8: =(K8-I8)/I8 -> -0.0073573482 | M8: =AD8 -> 5339537.9 | N8: =(M8-K8)/K8 -> 0.011478328 | O8: =AE8 -> 5403169.4 | P8: =(O8-M8)/M8 -> 0.011917046 | Q8: =AF8 -> 5475687.1 | R8: =(Q8-O8)/O8 -> 0.013421321 | S8: =AG8 -> 5554138.3 | T8: =(S8-Q8)/Q8 -> 0.0143272 | W8: ='7-1. FS'!AD7 -> 6724596.9 | X8: ='7-1. FS'!AE7 -> 6492488.3 | Y8: ='7-1. FS'!AF7 -> 5731760.4 | Z8: ='7-1. FS'!AG7 -> 5446774.4 | AA8: ='7-1. FS'!AH7 -> 5368881.7 | AB8: ='7-1. FS'!AI7 -> 5318071.3 | AC8: ='7-1. FS'!AJ7 -> 5278944.4 | AD8: ='7-1. FS'!AK7 -> 5339537.9 | ... AG8: ='7-1. FS'!AN7 -> 5554138.3 | AI8: 상태표 | AK8: 비유동자산 | AM8: 5357852 | AN8: 5.528 | AO8: 5430855 | AP8: 0.014 | AQ8: 5497157 | AR8: 0.012 | AS8: 5590222 | AT8: 0.017 | AU8: 5550548 | AV8: -0.007 | AX8: =#REF!-AM8 -> #REF! | AY8: =#REF!-AO8 -> #REF! | AZ8: =#REF!-AQ8 -> #REF! | BA8: =#REF!-AS8 -> #REF! | BB8: =E8-AU8 -> -99510.119 | BC8: =(AU8-AS8)/AS8 -> -0.0070970348 | BD8: =AV8-BC8 -> 9.7034787e-05
B9: 부채총계 | E9: =SUM(E10:E11) -> 3796297.1 | G9: =SUM(G10:G11) -> 3663172.6 | H9: =(G9-E9)/E9 -> -0.03506694 | I9: =SUM(I10:I11) -> 3614257.3 | J9: =(I9-G9)/G9 -> -0.013353269 | K9: =SUM(K10:K11) -> 3575964.5 | L9: =(K9-I9)/I9 -> -0.010594915 | M9: =SUM(M10:M11) -> 3551876.7 | N9: =(M9-K9)/K9 -> -0.0067360513 | O9: =SUM(O10:O11) -> 3534590 | P9: =(O9-M9)/M9 -> -0.0048669049 | Q9: =SUM(Q10:Q11) -> 3523282.1 | R9: =(Q9-O9)/O9 -> -0.0031992073 | S9: =SUM(S10:S11) -> 3518550.9 | T9: =(S9-Q9)/Q9 -> -0.0013428468 | AJ9: 부채총계 | AM9: 3413667 | AN9: 9.911 | AO9: 3411605 | AP9: -0.001 | AQ9: 3407808 | AR9: -0.001 | AS9: 3508037 | AT9: 0.029 | AU9: 3482792 | AV9: -0.007 | AX9: =#REF!-AM9 -> #REF! | AY9: =#REF!-AO9 -> #REF! | AZ9: =#REF!-AQ9 -> #REF! | BA9: =#REF!-AS9 -> #REF! | BB9: =E9-AU9 -> 313505.13 | BC9: =(AU9-AS9)/AS9 -> -0.0071963323 | BD9: =AV9-BC9 -> 0.00019633231
C10: 유동부채 | E10: ='1. 요약재무제표'!O10 -> 1726694.9 | G10: =AA10 -> 1793843.7 | H10: =(G10-E10)/E10 -> 0.038888667 | I10: =AB10 -> 1603385.6 | J10: =(I10-G10)/G10 -> -0.10617318 | K10: =AC10 -> 1613813 | L10: =(K10-I10)/I10 -> 0.0065033044 | M10: =AD10 -> 1631567.1 | N10: =(M10-K10)/K10 -> 0.011001363 | O10: =AE10 -> 1651298.1 | P10: =(O10-M10)/M10 -> 0.012093272 | Q10: =AF10 -> 1671790.3 | R10: =(Q10-O10)/O10 -> 0.012409774 | S10: =AG10 -> 1696078.5 | T10: =(S10-Q10)/Q10 -> 0.014528237 | W10: ='7-1. FS'!AD17 -> 1726933.7 | X10: ='7-1. FS'!AE17 -> 2077661.1 | Y10: ='7-1. FS'!AF17 -> 1747740.3 | Z10: ='7-1. FS'!AG17 -> 1726640.3 | AA10: ='7-1. FS'!AH17 -> 1793843.7 | AB10: ='7-1. FS'!AI17 -> 1603385.6 | AC10: ='7-1. FS'!AJ17 -> 1613813 | AD10: ='7-1. FS'!AK17 -> 1631567.1 | ... AG10: ='7-1. FS'!AN17 -> 1696078.5 | AK10: 유동부채 | AM10: 1326683 | AN10: 3.647 | AO10: 1605033 | AP10: 0.21 | AQ10: 1657701 | AR10: 0.033 | AS10: 1820972 | AT10: 0.098 | AU10: 2049481 | AV10: 0.125 | AX10: =#REF!-AM10 -> #REF! | AY10: =#REF!-AO10 -> #REF! | AZ10: =#REF!-AQ10 -> #REF! | BA10: =#REF!-AS10 -> #REF! | BB10: =E10-AU10 -> -322786.13 | BC10: =(AU10-AS10)/AS10 -> 0.12548738 | BD10: =AV10-BC10 -> -0.00048737707
C11: 비유동부채 | E11: ='1. 요약재무제표'!O11 -> 2069602.3 | G11: =AA11 -> 1869328.9 | H11: =(G11-E11)/E11 -> -0.096769022 | I11: =AB11 -> 2010871.6 | J11: =(I11-G11)/G11 -> 0.075718489 | K11: =AC11 -> 1962151.6 | L11: =(K11-I11)/I11 -> -0.024228327 | M11: =AD11 -> 1920309.6 | N11: =(M11-K11)/K11 -> -0.021324562 | O11: =AE11 -> 1883291.9 | P11: =(O11-M11)/M11 -> -0.019276908 | Q11: =AF11 -> 1851491.8 | R11: =(Q11-O11)/O11 -> -0.016885391 | S11: =AG11 -> 1822472.4 | T11: =(S11-Q11)/Q11 -> -0.01567352 | W11: ='7-1. FS'!AD18 -> 2107738.5 | X11: ='7-1. FS'!AE18 -> 2049126.1 | Y11: ='7-1. FS'!AF18 -> 2203694.5 | Z11: ='7-1. FS'!AG18 -> 2063974.7 | AA11: ='7-1. FS'!AH18 -> 1869328.9 | AB11: ='7-1. FS'!AI18 -> 2010871.6 | AC11: ='7-1. FS'!AJ18 -> 1962151.6 | AD11: ='7-1. FS'!AK18 -> 1920309.6 | ... AG11: ='7-1. FS'!AN18 -> 1822472.4 | AK11: 비유동부채 | AM11: 2086984 | AN11: 75.165 | AO11: 1806573 | AP11: -0.134 | AQ11: 1750107 | AR11: -0.031 | AS11: 1687065 | AT11: -0.036 | AU11: 1433311 | AV11: -0.15 | AX11: =#REF!-AM11 -> #REF! | AY11: =#REF!-AO11 -> #REF! | AZ11: =#REF!-AQ11 -> #REF! | BA11: =#REF!-AS11 -> #REF! | BB11: =E11-AU11 -> 636291.27 | BC11: =(AU11-AS11)/AS11 -> -0.15041151 | BD11: =AV11-BC11 -> 0.00041151349
B12: 자본총계 | E12: =SUM(E13:E17) -> 3325039.7 | G12: =SUM(G13:G17) -> 3438806.1 | H12: =(G12-E12)/E12 -> 0.03421504 | I12: =SUM(I13:I17) -> 3552334.3 | J12: =(I12-G12)/G12 -> 0.033013849 | K12: =SUM(K13:K17) -> 3653882 | L12: =(K12-I12)/I12 -> 0.028586189 | M12: =SUM(M13:M17) -> 3756866.6 | N12: =(M12-K12)/K12 -> 0.028184981 | O12: =SUM(O13:O17) -> 3871507.7 | P12: =(O12-M12)/M12 -> 0.030515077 | Q12: =SUM(Q13:Q17) -> 3986905 | R12: =(Q12-O12)/O12 -> 0.029806811 | S12: =SUM(S13:S17) -> 4108625.8 | T12: =(S12-Q12)/Q12 -> 0.030530159 | AJ12: 자본총계 | AM12: 3745335 | AN12: 1.999 | AO12: 4018174 | AP12: 0.073 | AQ12: 4321019 | AR12: 0.075 | AS12: 4706798 | AT12: 0.089 | AU12: 5176618 | AV12: 0.1 | AX12: =#REF!-AM12 -> #REF! | AY12: =#REF!-AO12 -> #REF! | AZ12: =#REF!-AQ12 -> #REF! | BA12: =#REF!-AS12 -> #REF! | BB12: =E12-AU12 -> -1851578.3 | BC12: =(AU12-AS12)/AS12 -> 0.099817328 | BD12: =AV12-BC12 -> 0.00018267196
C13: 자본금 | E13: ='1. 요약재무제표'!O13 -> 83607.415 | G13: =AA13 -> 83607.493 | H13: =(G13-E13)/E13 -> 9.3293161e-07 | I13: =AB13 -> 83607.493 | J13: =(I13-G13)/G13 -> 0 | K13: =AC13 -> 83607.493 | L13: =(K13-I13)/I13 -> 0 | M13: =AD13 -> 83607.493 | N13: =(M13-K13)/K13 -> 0 | O13: =AE13 -> 83607.493 | P13: =(O13-M13)/M13 -> 0 | Q13: =AF13 -> 83607.493 | R13: =(Q13-O13)/O13 -> 0 | S13: =AG13 -> 83607.493 | T13: =(S13-Q13)/Q13 -> 0 | W13: ='7-1. FS'!AD27 -> 104718 | X13: ='7-1. FS'!AE27 -> 104718 | Y13: ='7-1. FS'!AF27 -> 83607.493 | Z13: ='7-1. FS'!AG27 -> 83607 | AA13: ='7-1. FS'!AH27 -> 83607.493 | AB13: ='7-1. FS'!AI27 -> 83607.493 | AC13: ='7-1. FS'!AJ27 -> 83607.493 | AD13: ='7-1. FS'!AK27 -> 83607.493 | ... AG13: ='7-1. FS'!AN27 -> 83607.493 | AK13: 자본금 | AM13: 109813 | AN13: 2.347 | AO13: 109813 | AP13: 0 | AQ13: 109813 | AR13: 0 | AS13: 109813 | AT13: 0 | AU13: 109813 | AV13: 0 | AX13: =#REF!-AM13 -> #REF! | AY13: =#REF!-AO13 -> #REF! | AZ13: =#REF!-AQ13 -> #REF! | BA13: =#REF!-AS13 -> #REF! | BB13: =E13-AU13 -> -26205.585 | BC13: =(AU13-AS13)/AS13 -> 0 | BD13: =AV13-BC13 -> 0
C14: 자본잉여금 | E14: ='1. 요약재무제표'!O14 -> 966458.25 | G14: =AA14 -> 966458 | H14: =(G14-E14)/E14 -> -2.5956941e-07 | I14: =AB14 -> 966458 | J14: =(I14-G14)/G14 -> 0 | K14: =AC14 -> 966458 | L14: =(K14-I14)/I14 -> 0 | M14: =AD14 -> 966458 | N14: =(M14-K14)/K14 -> 0 | O14: =AE14 -> 966458 | P14: =(O14-M14)/M14 -> 0 | Q14: =AF14 -> 966458 | R14: =(Q14-O14)/O14 -> 0 | S14: =AG14 -> 966458 | T14: =(S14-Q14)/Q14 -> 0 | W14: ='7-1. FS'!AD28 -> 1195692.5 | X14: ='7-1. FS'!AE28 -> 1195692.5 | Y14: ='7-1. FS'!AF28 -> 966458.25 | Z14: ='7-1. FS'!AG28 -> 966458 | AA14: ='7-1. FS'!AH28 -> 966458 | AB14: ='7-1. FS'!AI28 -> 966458 | AC14: ='7-1. FS'!AJ28 -> 966458 | AD14: ='7-1. FS'!AK28 -> 966458 | ... AG14: ='7-1. FS'!AN28 -> 966458 | AK14: 자본잉여금 | AM14: 262644 | AN14: 1.376 | AO14: 262644 | AP14: 0 | AQ14: 262644 | AR14: 0 | AS14: 262644 | AT14: 0 | AU14: 262644 | AV14: 0 | AX14: =#REF!-AM14 -> #REF! | AY14: =#REF!-AO14 -> #REF! | AZ14: =#REF!-AQ14 -> #REF! | BA14: =#REF!-AS14 -> #REF! | BB14: =E14-AU14 -> 703814.25 | BC14: =(AU14-AS14)/AS14 -> 0 | BD14: =AV14-BC14 -> 0
C15: 기타포괄손익누계액 | E15: ='1. 요약재무제표'!O15 -> 125770.59 | G15: =AA15 -> 125771 | H15: =(G15-E15)/E15 -> 3.2638235e-06 | I15: =AB15 -> 125771 | J15: =(I15-G15)/G15 -> 0 | K15: =AC15 -> 125771 | L15: =(K15-I15)/I15 -> 0 | M15: =AD15 -> 125771 | N15: =(M15-K15)/K15 -> 0 | O15: =AE15 -> 125771 | P15: =(O15-M15)/M15 -> 0 | Q15: =AF15 -> 125771 | R15: =(Q15-O15)/O15 -> 0 | S15: =AG15 -> 125771 | T15: =(S15-Q15)/Q15 -> 0 | W15: ='7-1. FS'!AD33 -> 44540.656 | X15: ='7-1. FS'!AE33 -> 61373.205 | Y15: ='7-1. FS'!AF33 -> 86173.492 | Z15: ='7-1. FS'!AG33 -> 125771 | AA15: ='7-1. FS'!AH33 -> 125771 | AB15: ='7-1. FS'!AI33 -> 125771 | AC15: ='7-1. FS'!AJ33 -> 125771 | AD15: ='7-1. FS'!AK33 -> 125771 | ... AG15: ='7-1. FS'!AN33 -> 125771 | AK15: 기타포괄손익누계액 | AM15: 13139 | AN15: -0.121 | AO15: 13139 | AP15: 0 | AQ15: 13139 | AR15: 0 | AS15: 13139 | AT15: 0 | AU15: 13139 | AV15: 0 | AX15: =#REF!-AM15 -> #REF! | AY15: =#REF!-AO15 -> #REF! | AZ15: =#REF!-AQ15 -> #REF! | BA15: =#REF!-AS15 -> #REF! | BB15: =E15-AU15 -> 112631.59 | BC15: =(AU15-AS15)/AS15 -> 0 | BD15: =AV15-BC15 -> 0
C16: 이익잉여금 | E16: ='1. 요약재무제표'!O16 -> 2750737.4 | G16: =AA16 -> 2864503.6 | H16: =(G16-E16)/E16 -> 0.04135843 | I16: =AB16 -> 2978031.8 | J16: =(I16-G16)/G16 -> 0.039632774 | K16: =AC16 -> 3079579.5 | L16: =(K16-I16)/I16 -> 0.03409893 | M16: =AD16 -> 3182564.1 | N16: =(M16-K16)/K16 -> 0.033441122 | O16: =AE16 -> 3297205.2 | P16: =(O16-M16)/M16 -> 0.036021607 | Q16: =AF16 -> 3412602.5 | R16: =(Q16-O16)/O16 -> 0.034998519 | S16: =AG16 -> 3534323.3 | T16: =(S16-Q16)/Q16 -> 0.03566804 | W16: ='7-1. FS'!AD29 -> 2865790.2 | X16: ='7-1. FS'!AE29 -> 2791700.9 | Y16: ='7-1. FS'!AF29 -> 2670425.8 | Z16: ='7-1. FS'!AG29 -> 2754868.7 | AA16: ='7-1. FS'!AH29 -> 2864503.6 | AB16: ='7-1. FS'!AI29 -> 2978031.8 | AC16: ='7-1. FS'!AJ29 -> 3079579.5 | AD16: ='7-1. FS'!AK29 -> 3182564.1 | ... AG16: ='7-1. FS'!AN29 -> 3534323.3 | AK16: 이익잉여금 | AM16: 3468537 | AN16: 1.892 | AO16: 3741376 | AP16: 0.079 | AQ16: 4044222 | AR16: 0.081 | AS16: 4430001 | AT16: 0.095 | AU16: 4899821 | AV16: 0.106 | AX16: =#REF!-AM16 -> #REF! | AY16: =#REF!-AO16 -> #REF! | AZ16: =#REF!-AQ16 -> #REF! | BA16: =#REF!-AS16 -> #REF! | BB16: =E16-AU16 -> -2149083.6 | BC16: =(AU16-AS16)/AS16 -> 0.10605415 | BD16: =AV16-BC16 -> -5.4152132e-05
C17: 기타자본항목 | E17: ='1. 요약재무제표'!O17 -> -601533.95 | G17: =AA17 -> -601534 | H17: =(G17-E17)/E17 -> 8.3167376e-08 | I17: =AB17 -> -601534 | J17: =(I17-G17)/G17 -> 0 | K17: =AC17 -> -601534 | L17: =(K17-I17)/I17 -> 0 | M17: =AD17 -> -601534 | N17: =(M17-K17)/K17 -> 0 | O17: =AE17 -> -601534 | P17: =(O17-M17)/M17 -> 0 | Q17: =AF17 -> -601534 | R17: =(Q17-O17)/O17 -> 0 | S17: =AG17 -> -601534 | T17: =(S17-Q17)/Q17 -> 0 | W17: ='7-1. FS'!AD32 -> -98183.617 | X17: ='7-1. FS'!AE32 -> -68183.615 | Y17: ='7-1. FS'!AF32 -> -601533.95 | Z17: ='7-1. FS'!AG32 -> -601534 | AA17: ='7-1. FS'!AH32 -> -601534 | AB17: ='7-1. FS'!AI32 -> -601534 | AC17: ='7-1. FS'!AJ32 -> -601534 | AD17: ='7-1. FS'!AK32 -> -601534 | ... AG17: ='7-1. FS'!AN32 -> -601534 | AK17: 자본조정 | AM17: -108799 | AN17: 0.001 | AO17: -108799 | AP17: 0 | AQ17: -108799 | AR17: 0 | AS17: -108799 | AT17: 0 | AU17: -108799 | AV17: 0 | AX17: =#REF!-AM17 -> #REF! | AY17: =#REF!-AO17 -> #REF! | AZ17: =#REF!-AQ17 -> #REF! | BA17: =#REF!-AS17 -> #REF! | BB17: =E17-AU17 -> -492734.95 | BC17: =(AU17-AS17)/AS17 -> 0 | BD17: =AV17-BC17 -> 0
A18: 요약손익계산서 | B18: 매출액 | E18: =E19+E26 -> 11774644 | G18: =G19+G26 -> 12032603 | H18: =(G18-E18)/E18 -> 0.021908034 | I18: =I19+I26 -> 12216426 | J18: =(I18-G18)/G18 -> 0.015277099 | K18: =K19+K26 -> 12411089 | L18: =(K18-I18)/I18 -> 0.015934511 | M18: =M19+M26 -> 12626306 | N18: =(M18-K18)/K18 -> 0.017340684 | O18: =O19+O26 -> 12850431 | P18: =(O18-M18)/M18 -> 0.017750609 | Q18: =Q19+Q26 -> 13103491 | R18: =(Q18-O18)/O18 -> 0.019692722 | S18: =S19+S26 -> 13382836 | T18: =(S18-Q18)/Q18 -> 0.021318364 | AI18: 요약 | AJ18: 매출액 | AM18: 10241785 | AN18: 7.487 | AO18: 11844133 | AP18: 0.156 | AQ18: 12654110 | AR18: 0.068 | AS18: 13664771 | AT18: 0.08 | AU18: 14769066 | AV18: 0.081 | AX18: =#REF!-AM18 -> #REF! | AY18: =#REF!-AO18 -> #REF! | AZ18: =#REF!-AQ18 -> #REF! | BA18: =#REF!-AS18 -> #REF! | BB18: =E18-AU18 -> -2994422.1 | BC18: =(AU18-AS18)/AS18 -> 0.080813283 | BD18: =AV18-BC18 -> 0.00018671744
C19: [1] 홈쇼핑부문 | E19: =SUM(E20:E22) -> 1049110.2 | G19: =SUM(G20:G22) -> 1060021.4 | H19: =(G19-E19)/E19 -> 0.010400464 | I19: =SUM(I20:I22) -> 1054370.4 | J19: =(I19-G19)/G19 -> -0.0053310454 | K19: =SUM(K20:K22) -> 1048778.8 | L19: =(K19-I19)/I19 -> -0.0053032676 | M19: =SUM(M20:M22) -> 1043246 | N19: =(M19-K19)/K19 -> -0.0052754898 | O19: =SUM(O20:O22) -> 1038379.9 | P19: =(O19-M19)/M19 -> -0.0046643787 | Q19: =SUM(Q20:Q22) -> 1034574.9 | R19: =(Q19-O19)/O19 -> -0.0036643787 | S19: =SUM(S20:S22) -> 1031990.8 | T19: =(S19-Q19)/Q19 -> -0.0024977121 | AI19: 손익 | AK19: [1] GS홈쇼핑 | AM19: 1304180 | AN19: 0.081 | AO19: 1411122 | AP19: 0.082 | AQ19: 1488734 | AR19: 0.055 | AS19: 1555727 | AT19: 0.045 | AU19: 1614844 | AV19: 0.038 | AX19: =#REF!-AM19 -> #REF! | AY19: =#REF!-AO19 -> #REF! | AZ19: =#REF!-AQ19 -> #REF! | BA19: =#REF!-AS19 -> #REF! | BB19: =E19-AU19 -> -565733.81 | BC19: =(AU19-AS19)/AS19 -> 0.037999598 | BD19: =AV19-BC19 -> 4.0238422e-07
C20: (방송사업매출액) | E20: ='1. 요약재무제표'!O20 -> 333966.8 | G20: =AA20 -> 325005.55 | H20: =(G20-E20)/E20 -> -0.026832772 | I20: =AB20 -> 318449.85 | J20: =(I20-G20)/G20 -> -0.020171013 | K20: =AC20 -> 314768.82 | L20: =(K20-I20)/I20 -> -0.011559226 | M20: =AD20 -> 312593.36 | N20: =(M20-K20)/K20 -> -0.0069113069 | O20: =AE20 -> 311278.87 | P20: =(O20-M20)/M20 -> -0.0042051098 | Q20: =AF20 -> 310422.04 | R20: =(Q20-O20)/O20 -> -0.0027525921 | S20: =AG20 -> 310012.32 | T20: =(S20-Q20)/Q20 -> -0.0013198853 | U20: 데이터홈쇼핑 및 TV홈쇼핑 수수료매출, 광고매출 | W20: ='9. 추정 IS'!G37+'9. 추정 IS'!G38 -> 367350 | X20: ='9. 추정 IS'!H37+'9. 추정 IS'!H38 -> 346760.93 | Y20: ='9. 추정 IS'!I37+'9. 추정 IS'!I38 -> 311281.54 | Z20: ='9. 추정 IS'!J37+'9. 추정 IS'!J38 -> 333966.8 | AA20: ='9. 추정 IS'!K37+'9. 추정 IS'!K38 -> 325005.55 | AB20: ='9. 추정 IS'!L37+'9. 추정 IS'!L38 -> 318449.85 | AC20: ='9. 추정 IS'!M37+'9. 추정 IS'!M38 -> 314768.82 | AD20: ='9. 추정 IS'!N37+'9. 추정 IS'!N38 -> 312593.36 | ... AG20: ='9. 추정 IS'!Q37+'9. 추정 IS'!Q38 -> 310012.32 | AI20: 계산서 | AK20: 방송사업매출액 | AM20: 346721 | AN20: -0.059 | AO20: 343448 | AP20: -0.009 | AQ20: 341483 | AR20: -0.006 | AS20: 339766 | AT20: -0.005 | AU20: 321998 | AV20: -0.052 | AX20: =#REF!-AM20 -> #REF! | AY20: =#REF!-AO20 -> #REF! | AZ20: =#REF!-AQ20 -> #REF! | BA20: =#REF!-AS20 -> #REF! | BB20: =E20-AU20 -> 11968.8 | BC20: =(AU20-AS20)/AS20 -> -0.052294815 | BD20: =AV20-BC20 -> 0.00029481467
C21: (방송상품매출액) | E21: ='1. 요약재무제표'!O21 -> 84255.337 | G21: =AA21 -> 85121.529 | H21: =(G21-E21)/E21 -> 0.01028056 | I21: =AB21 -> 85270.654 | J21: =(I21-G21)/G21 -> 0.0017519006 | K21: =AC21 -> 84797.963 | L21: =(K21-I21)/I21 -> -0.0055434145 | M21: =AD21 -> 83980.465 | N21: =(M21-K21)/K21 -> -0.0096405463 | O21: =AE21 -> 82931.454 | P21: =(O21-M21)/M21 -> -0.012491127 | Q21: =AF21 -> 81708.289 | R21: =(Q21-O21)/O21 -> -0.014749111 | S21: =AG21 -> 80343.91 | T21: =(S21-Q21)/Q21 -> -0.016698164 | U21: 데이터홈쇼핑 및 TV홈쇼핑 상품매출(직매입) | W21: ='9. 추정 IS'!G31+'9. 추정 IS'!G32 -> 106344 | X21: ='9. 추정 IS'!H31+'9. 추정 IS'!H32 -> 89694.981 | Y21: ='9. 추정 IS'!I31+'9. 추정 IS'!I32 -> 76110.235 | Z21: ='9. 추정 IS'!J31+'9. 추정 IS'!J32 -> 84255.337 | AA21: ='9. 추정 IS'!K31+'9. 추정 IS'!K32 -> 85121.529 | AB21: ='9. 추정 IS'!L31+'9. 추정 IS'!L32 -> 85270.654 | AC21: ='9. 추정 IS'!M31+'9. 추정 IS'!M32 -> 84797.963 | AD21: ='9. 추정 IS'!N31+'9. 추정 IS'!N32 -> 83980.465 | ... AG21: ='9. 추정 IS'!Q31+'9. 추정 IS'!Q32 -> 80343.91 | AK21: 방송상품매출액 | AM21: 152786 | AN21: 0.451 | AO21: 183471 | AP21: 0.201 | AQ21: 200122 | AR21: 0.091 | AS21: 211276 | AT21: 0.056 | AU21: 218975 | AV21: 0.036 | AX21: =#REF!-AM21 -> #REF! | AY21: =#REF!-AO21 -> #REF! | AZ21: =#REF!-AQ21 -> #REF! | BA21: =#REF!-AS21 -> #REF! | BB21: =E21-AU21 -> -134719.66 | BC21: =(AU21-AS21)/AS21 -> 0.036440485 | BD21: =AV21-BC21 -> -0.00044048543
C22: (기타사업매출액) | E22: =SUM(E23:E25) -> 630888.05 | G22: =SUM(G23:G25) -> 649894.35 | H22: =(G22-E22)/E22 -> 0.030126257 | I22: =SUM(I23:I25) -> 650649.89 | J22: =(I22-G22)/G22 -> 0.0011625647 | K22: =SUM(K23:K25) -> 649212.01 | L22: =(K22-I22)/I22 -> -0.0022099198 | M22: =SUM(M23:M25) -> 646672.15 | N22: =(M22-K22)/K22 -> -0.0039122186 | O22: =SUM(O23:O25) -> 644169.55 | P22: =(O22-M22)/M22 -> -0.0038699584 | Q22: =SUM(Q23:Q25) -> 642444.52 | R22: =(Q22-O22)/O22 -> -0.00267791 | S22: =SUM(S23:S25) -> 641634.55 | T22: =(S22-Q22)/Q22 -> -0.0012607628 | AK22: 기타사업매출액 | AM22: 804673 | AN22: 0.098 | AO22: 884204 | AP22: 0.099 | AQ22: 947128 | AR22: 0.071 | AS22: 1004685 | AT22: 0.061 | AU22: 1073871 | AV22: 0.069 | AX22: =#REF!-AM22 -> #REF! | AY22: =#REF!-AO22 -> #REF! | AZ22: =#REF!-AQ22 -> #REF! | BA22: =#REF!-AS22 -> #REF! | BB22: =E22-AU22 -> -442982.95 | BC22: =(AU22-AS22)/AS22 -> 0.068863375 | BD22: =AV22-BC22 -> 0.00013662491
D23: [카탈로그매출액] | E23: ='1. 요약재무제표'!O23 -> 0 | G23: =AA23 -> 0 | I23: =AB23 -> 0 | K23: =AC23 -> 0 | M23: =AD23 -> 0 | O23: =AE23 -> 0 | Q23: =AF23 -> 0 | S23: =AG23 -> 0 | W23: ='9. 추정 IS'!G28 -> 0 | X23: ='9. 추정 IS'!H28 -> 0 | Y23: ='9. 추정 IS'!I28 -> 0 | Z23: ='9. 추정 IS'!J28 -> 0 | AA23: ='9. 추정 IS'!K28 -> 0 | AB23: ='9. 추정 IS'!L28 -> 0 | AC23: ='9. 추정 IS'!M28 -> 0 | AD23: ='9. 추정 IS'!N28 -> 0 | ... AG23: ='9. 추정 IS'!Q28 -> 0 | AL23: 카탈로그매출액 | AM23: 0 | AO23: 0 | AQ23: 0 | AS23: 0 | AU23: 0 | AX23: =#REF!-AM23 -> #REF! | AY23: =#REF!-AO23 -> #REF! | AZ23: =#REF!-AQ23 -> #REF! | BA23: =#REF!-AS23 -> #REF! | BB23: =E23-AU23 -> 0 | BC23: =(AU23-AS23)/AS23 -> #DIV/0! | BD23: =AV23-BC23 -> #DIV/0!
D24: [모바일인터넷매출액] | E24: ='1. 요약재무제표'!O24 -> 611356.65 | G24: =AA24 -> 623450.73 | H24: =(G24-E24)/E24 -> 0.019782368 | I24: =AB24 -> 629155.51 | J24: =(I24-G24)/G24 -> 0.0091503398 | K24: =AC24 -> 630491.07 | L24: =(K24-I24)/I24 -> 0.0021227803 | M24: =AD24 -> 629598.38 | N24: =(M24-K24)/K24 -> -0.0014158638 | O24: =AE24 -> 628112.58 | P24: =(O24-M24)/M24 -> -0.0023599287 | Q24: =AF24 -> 627031.54 | R24: =(Q24-O24)/O24 -> -0.0017210887 | S24: =AG24 -> 626636.48 | T24: =(S24-Q24)/Q24 -> -0.00063004311 | W24: ='9. 추정 IS'!G27 -> 732689 | X24: ='9. 추정 IS'!H27 -> 675496.46 | Y24: ='9. 추정 IS'!I27 -> 648115.45 | Z24: ='9. 추정 IS'!J27 -> 611356.65 | AA24: ='9. 추정 IS'!K27 -> 623450.73 | AB24: ='9. 추정 IS'!L27 -> 629155.51 | AC24: ='9. 추정 IS'!M27 -> 630491.07 | AD24: ='9. 추정 IS'!N27 -> 629598.38 | ... AG24: ='9. 추정 IS'!Q27 -> 626636.48 | AL24: 모바일/온라인매출액 | AM24: 763873 | AN24: 0.109 | AO24: 847477 | AP24: 0.109 | AQ24: 916207 | AR24: 0.081 | AS24: 980551 | AT24: 0.07 | AU24: 1065797 | AV24: 0.087 | AX24: =#REF!-AM24 -> #REF! | AY24: =#REF!-AO24 -> #REF! | AZ24: =#REF!-AQ24 -> #REF! | BA24: =#REF!-AS24 -> #REF! | BB24: =E24-AU24 -> -454440.35 | BC24: =(AU24-AS24)/AS24 -> 0.086936834 | BD24: =AV24-BC24 -> 6.3165506e-05
D25: [기타매출액] | E25: ='1. 요약재무제표'!O25 -> 19531.404 | G25: =AA25 -> 26443.617 | H25: =(G25-E25)/E25 -> 0.35390255 | I25: =AB25 -> 21494.376 | J25: =(I25-G25)/G25 -> -0.18716206 | K25: =AC25 -> 18720.933 | L25: =(K25-I25)/I25 -> -0.1290311 | M25: =AD25 -> 17073.763 | N25: =(M25-K25)/K25 -> -0.087985456 | O25: =AE25 -> 16056.976 | P25: =(O25-M25)/M25 -> -0.059552602 | Q25: =AF25 -> 15412.985 | R25: =(Q25-O25)/O25 -> -0.040106599 | S25: =AG25 -> 14998.072 | T25: =(S25-Q25)/Q25 -> -0.026919721 | W25: ='9. 추정 IS'!G29 -> 32932 | X25: ='9. 추정 IS'!H29 -> 19113.03 | Y25: ='9. 추정 IS'!I29 -> 16572.112 | Z25: ='9. 추정 IS'!J29 -> 19531.404 | AA25: ='9. 추정 IS'!K29 -> 26443.617 | AB25: ='9. 추정 IS'!L29 -> 21494.376 | AC25: ='9. 추정 IS'!M29 -> 18720.933 | AD25: ='9. 추정 IS'!N29 -> 17073.763 | ... AG25: ='9. 추정 IS'!Q29 -> 14998.072 | AL25: 기타매출액 | AM25: 40800 | AN25: -0.075 | AO25: 36727 | AP25: -0.1 | AQ25: 30921 | AR25: -0.158 | AS25: 24135 | AT25: -0.219 | AU25: 8074 | AV25: -0.665 | AX25: =#REF!-AM25 -> #REF! | AY25: =#REF!-AO25 -> #REF! | AZ25: =#REF!-AQ25 -> #REF! | BA25: =#REF!-AS25 -> #REF! | BB25: =E25-AU25 -> 11457.404 | BC25: =(AU25-AS25)/AS25 -> -0.66546509 | BD25: =AV25-BC25 -> 0.00046509219
C26: [2] 리테일부문 | E26: ='1. 요약재무제표'!O26 -> 10725534 | G26: =AA26 -> 10972582 | H26: =(G26-E26)/E26 -> 0.023033639 | I26: =AB26 -> 11162056 | J26: =(I26-G26)/G26 -> 0.017267977 | K26: =AC26 -> 11362310 | L26: =(K26-I26)/I26 -> 0.017940636 | M26: =AD26 -> 11583060 | N26: =(M26-K26)/K26 -> 0.019428231 | O26: =AE26 -> 11812051 | P26: =(O26-M26)/M26 -> 0.019769449 | Q26: =AF26 -> 12068916 | R26: =(Q26-O26)/O26 -> 0.02174601 | S26: =AG26 -> 12350845 | T26: =(S26-Q26)/Q26 -> 0.023359932 | W26: ='7-1. FS'!AD51 -> 9330023.1 | X26: ='7-1. FS'!AE51 -> 9755829.7 | Y26: ='7-1. FS'!AF51 -> 10325953 | Z26: ='7-1. FS'!AG51 -> 10725534 | AA26: ='7-1. FS'!AH51 -> 10972582 | AB26: ='7-1. FS'!AI51 -> 11162056 | AC26: ='7-1. FS'!AJ51 -> 11362310 | AD26: ='7-1. FS'!AK51 -> 11583060 | ... AG26: ='7-1. FS'!AN51 -> 12350845 | AK26: [2] GS리테일 | AM26: 8934808 | AO26: 10385196 | AP26: 0.162 | AQ26: 10967934 | AR26: 0.056 | AS26: 11651368 | AT26: 0.062 | AU26: 12267340 | AV26: 0.053 | AX26: =#REF!-AM26 -> #REF! | AY26: =#REF!-AO26 -> #REF! | AZ26: =#REF!-AQ26 -> #REF! | BA26: =#REF!-AS26 -> #REF! | BB26: =E26-AU26 -> -1541806.3 | BC26: =(AU26-AS26)/AS26 -> 0.052866925 | BD26: =AV26-BC26 -> 0.00013307485
B27: 매출원가 | E27: =E28+E29 -> 8902467.3 | G27: =G28+G29 -> 9008909.3 | H27: =(G27-E27)/E27 -> 0.011956454 | I27: =I28+I29 -> 9186266.5 | J27: =(I27-G27)/G27 -> 0.019686871 | K27: =K28+K29 -> 9371141.1 | L27: =(K27-I27)/I27 -> 0.020125107 | M27: =M28+M29 -> 9570388.4 | N27: =(M27-K27)/K27 -> 0.0212618 | O27: =O28+O29 -> 9763257.2 | P27: =(O27-M27)/M27 -> 0.020152661 | Q27: =Q28+Q29 -> 9977799.4 | R27: =(Q27-O27)/O27 -> 0.021974444 | S27: =S28+S29 -> 10211276 | T27: =(S27-Q27)/Q27 -> 0.023399607 | AJ27: 매출원가 | AM27: 7357110 | AN27: 35.619 | AO27: 8565286 | AP27: 0.164 | AQ27: 9097444 | AR27: 0.062 | AS27: 9732403 | AT27: 0.07 | AU27: 10368448 | AV27: 0.065 | AX27: =#REF!-AM27 -> #REF! | AY27: =#REF!-AO27 -> #REF! | AZ27: =#REF!-AQ27 -> #REF! | BA27: =#REF!-AS27 -> #REF! | BB27: =E27-AU27 -> -1465980.7 | BC27: =(AU27-AS27)/AS27 -> 0.065353336 | BD27: =AV27-BC27 -> -0.00035333566
C28: [1] 홈쇼핑부문 | E28: ='1. 요약재무제표'!O28 -> 139480.35 | G28: =AA28 -> 139521.17 | H28: =(G28-E28)/E28 -> 0.00029265563 | I28: =AB28 -> 142806.92 | J28: =(I28-G28)/G28 -> 0.023550244 | K28: =AC28 -> 146933.36 | L28: =(K28-I28)/I28 -> 0.028895173 | M28: =AD28 -> 149721.2 | N28: =(M28-K28)/K28 -> 0.018973563 | O28: =AE28 -> 152455.24 | P28: =(O28-M28)/M28 -> 0.018260866 | Q28: =AF28 -> 155104.04 | R28: =(Q28-O28)/O28 -> 0.017374252 | S28: =AG28 -> 157583.31 | T28: =(S28-Q28)/Q28 -> 0.015984589 | W28: ='7-1. FS'!AD53 -> 187896 | X28: ='7-1. FS'!AE53 -> 149269 | Y28: ='7-1. FS'!AF53 -> 119598 | Z28: ='7-1. FS'!AG53 -> 139480.35 | AA28: ='7-1. FS'!AH53 -> 139521.17 | AB28: ='7-1. FS'!AI53 -> 142806.92 | AC28: ='7-1. FS'!AJ53 -> 146933.36 | AD28: ='7-1. FS'!AK53 -> 149721.2 | ... AG28: ='7-1. FS'!AN53 -> 157583.31 | AK28: [1] GS홈쇼핑 | AM28: 291321 | AN28: 0.45 | AO28: 349585 | AP28: 0.2 | AQ28: 381048 | AR28: 0.09 | AS28: 402005 | AT28: 0.055 | AU28: 416076 | AV28: 0.035 | AX28: =#REF!-AM28 -> #REF! | AY28: =#REF!-AO28 -> #REF! | AZ28: =#REF!-AQ28 -> #REF! | BA28: =#REF!-AS28 -> #REF! | BB28: =E28-AU28 -> -276595.65 | BC28: =(AU28-AS28)/AS28 -> 0.035002052 | BD28: =AV28-BC28 -> -2.0522133e-06
C29: [2] 리테일부문 | E29: ='1. 요약재무제표'!O29 -> 8762987 | G29: =AA29 -> 8869388.1 | H29: =(G29-E29)/E29 -> 0.012142106 | I29: =AB29 -> 9043459.6 | J29: =(I29-G29)/G29 -> 0.019626098 | K29: =AC29 -> 9224207.7 | L29: =(K29-I29)/I29 -> 0.019986618 | M29: =AD29 -> 9420667.2 | N29: =(M29-K29)/K29 -> 0.02129825 | O29: =AE29 -> 9610802 | P29: =(O29-M29)/M29 -> 0.020182727 | Q29: =AF29 -> 9822695.3 | R29: =(Q29-O29)/O29 -> 0.022047417 | S29: =AG29 -> 10053693 | T29: =(S29-Q29)/Q29 -> 0.023516693 | W29: ='7-1. FS'!AD54 -> 7522688.4 | X29: ='7-1. FS'!AE54 -> 7836897.9 | Y29: ='7-1. FS'!AF54 -> 8333322 | Z29: ='7-1. FS'!AG54 -> 8671279 | AA29: ='7-1. FS'!AH54 -> 8869388.1 | AB29: ='7-1. FS'!AI54 -> 9043459.6 | AC29: ='7-1. FS'!AJ54 -> 9224207.7 | AD29: ='7-1. FS'!AK54 -> 9420667.2 | ... AG29: ='7-1. FS'!AN54 -> 10053693 | AK29: [2] GS리테일 | AM29: 7101563 | AO29: 8261953 | AP29: 0.163 | AQ29: 8715671 | AR29: 0.055 | AS29: 9237093 | AT29: 0.06 | AU29: 9697193 | AV29: 0.05 | AX29: =#REF!-AM29 -> #REF! | AY29: =#REF!-AO29 -> #REF! | AZ29: =#REF!-AQ29 -> #REF! | BA29: =#REF!-AS29 -> #REF! | BB29: =E29-AU29 -> -934206.03 | BC29: =(AU29-AS29)/AS29 -> 0.049810043 | BD29: =AV29-BC29 -> 0.00018995695
